2019-09-01 15:37:16,739 [Thread-1:5504] [service_mart.common.decorator:52] [ERROR]- error:error response:'Manager' object has no attribute 'filter_not_deleted'
2019-09-01 15:37:16,742 [Thread-1:5504] [service_mart.helper.middleware:163] [ERROR]- {{{
Traceback (most recent call last):

  File "C:\Users\项波\Desktop\flower-service\venv\lib\site-packages\django\core\handlers\base.py", line 113, in _get_response
    response = wrapped_callback(request, *callback_args, **callback_kwargs)

  File "C:\Users\项波\Desktop\flower-service\src\apps\common\decorator.py", line 17, in _func
    resp = func(*args, **kwargs)

  File "C:\Users\项波\Desktop\flower-service\venv\lib\site-packages\django\views\decorators\csrf.py", line 54, in wrapped_view
    return view_func(*args, **kwargs)

  File "C:\Users\项波\Desktop\flower-service\venv\lib\site-packages\django\views\generic\base.py", line 71, in view
    return self.dispatch(request, *args, **kwargs)

  File "C:\Users\项波\Desktop\flower-service\venv\lib\site-packages\rest_framework\views.py", line 497, in dispatch
    response = self.handle_exception(exc)

  File "C:\Users\项波\Desktop\flower-service\venv\lib\site-packages\rest_framework\views.py", line 457, in handle_exception
    self.raise_uncaught_exception(exc)

  File "C:\Users\项波\Desktop\flower-service\venv\lib\site-packages\rest_framework\views.py", line 468, in raise_uncaught_exception
    raise exc

  File "C:\Users\项波\Desktop\flower-service\venv\lib\site-packages\rest_framework\views.py", line 494, in dispatch
    response = handler(request, *args, **kwargs)

  File "C:\Users\项波\Desktop\flower-service\venv\lib\site-packages\rest_framework\decorators.py", line 50, in handler
    return func(*args, **kwargs)

  File "C:\Users\项波\Desktop\flower-service\src\apps\index\apis.py", line 12, in index_img
    index_imgs = IndexImg.objects.filter_not_deleted()

AttributeError: 'Manager' object has no attribute 'filter_not_deleted'

}}}

{{{
<WSGIRequest: GET '/api/index/indexImg/'>
}}}
Traceback (most recent call last):
  File "C:\Users\项波\Desktop\flower-service\venv\lib\site-packages\django\core\handlers\base.py", line 113, in _get_response
    response = wrapped_callback(request, *callback_args, **callback_kwargs)
  File "C:\Users\项波\Desktop\flower-service\src\apps\common\decorator.py", line 17, in _func
    resp = func(*args, **kwargs)
  File "C:\Users\项波\Desktop\flower-service\venv\lib\site-packages\django\views\decorators\csrf.py", line 54, in wrapped_view
    return view_func(*args, **kwargs)
  File "C:\Users\项波\Desktop\flower-service\venv\lib\site-packages\django\views\generic\base.py", line 71, in view
    return self.dispatch(request, *args, **kwargs)
  File "C:\Users\项波\Desktop\flower-service\venv\lib\site-packages\rest_framework\views.py", line 497, in dispatch
    response = self.handle_exception(exc)
  File "C:\Users\项波\Desktop\flower-service\venv\lib\site-packages\rest_framework\views.py", line 457, in handle_exception
    self.raise_uncaught_exception(exc)
  File "C:\Users\项波\Desktop\flower-service\venv\lib\site-packages\rest_framework\views.py", line 468, in raise_uncaught_exception
    raise exc
  File "C:\Users\项波\Desktop\flower-service\venv\lib\site-packages\rest_framework\views.py", line 494, in dispatch
    response = handler(request, *args, **kwargs)
  File "C:\Users\项波\Desktop\flower-service\venv\lib\site-packages\rest_framework\decorators.py", line 50, in handler
    return func(*args, **kwargs)
  File "C:\Users\项波\Desktop\flower-service\src\apps\index\apis.py", line 12, in index_img
    index_imgs = IndexImg.objects.filter_not_deleted()
AttributeError: 'Manager' object has no attribute 'filter_not_deleted'
2019-09-01 15:37:22,988 [Thread-1:5504] [service_mart.common.decorator:52] [ERROR]- error:error response:'Manager' object has no attribute 'filter_not_deleted'
2019-09-01 15:37:22,989 [Thread-1:5504] [service_mart.helper.middleware:163] [ERROR]- {{{
Traceback (most recent call last):

  File "C:\Users\项波\Desktop\flower-service\venv\lib\site-packages\django\core\handlers\base.py", line 113, in _get_response
    response = wrapped_callback(request, *callback_args, **callback_kwargs)

  File "C:\Users\项波\Desktop\flower-service\src\apps\common\decorator.py", line 17, in _func
    resp = func(*args, **kwargs)

  File "C:\Users\项波\Desktop\flower-service\venv\lib\site-packages\django\views\decorators\csrf.py", line 54, in wrapped_view
    return view_func(*args, **kwargs)

  File "C:\Users\项波\Desktop\flower-service\venv\lib\site-packages\django\views\generic\base.py", line 71, in view
    return self.dispatch(request, *args, **kwargs)

  File "C:\Users\项波\Desktop\flower-service\venv\lib\site-packages\rest_framework\views.py", line 497, in dispatch
    response = self.handle_exception(exc)

  File "C:\Users\项波\Desktop\flower-service\venv\lib\site-packages\rest_framework\views.py", line 457, in handle_exception
    self.raise_uncaught_exception(exc)

  File "C:\Users\项波\Desktop\flower-service\venv\lib\site-packages\rest_framework\views.py", line 468, in raise_uncaught_exception
    raise exc

  File "C:\Users\项波\Desktop\flower-service\venv\lib\site-packages\rest_framework\views.py", line 494, in dispatch
    response = handler(request, *args, **kwargs)

  File "C:\Users\项波\Desktop\flower-service\venv\lib\site-packages\rest_framework\decorators.py", line 50, in handler
    return func(*args, **kwargs)

  File "C:\Users\项波\Desktop\flower-service\src\apps\index\apis.py", line 12, in index_img
    index_imgs = IndexImg.objects.filter_not_deleted()

AttributeError: 'Manager' object has no attribute 'filter_not_deleted'

}}}

{{{
<WSGIRequest: GET '/api/index/indexImg/'>
}}}
Traceback (most recent call last):
  File "C:\Users\项波\Desktop\flower-service\venv\lib\site-packages\django\core\handlers\base.py", line 113, in _get_response
    response = wrapped_callback(request, *callback_args, **callback_kwargs)
  File "C:\Users\项波\Desktop\flower-service\src\apps\common\decorator.py", line 17, in _func
    resp = func(*args, **kwargs)
  File "C:\Users\项波\Desktop\flower-service\venv\lib\site-packages\django\views\decorators\csrf.py", line 54, in wrapped_view
    return view_func(*args, **kwargs)
  File "C:\Users\项波\Desktop\flower-service\venv\lib\site-packages\django\views\generic\base.py", line 71, in view
    return self.dispatch(request, *args, **kwargs)
  File "C:\Users\项波\Desktop\flower-service\venv\lib\site-packages\rest_framework\views.py", line 497, in dispatch
    response = self.handle_exception(exc)
  File "C:\Users\项波\Desktop\flower-service\venv\lib\site-packages\rest_framework\views.py", line 457, in handle_exception
    self.raise_uncaught_exception(exc)
  File "C:\Users\项波\Desktop\flower-service\venv\lib\site-packages\rest_framework\views.py", line 468, in raise_uncaught_exception
    raise exc
  File "C:\Users\项波\Desktop\flower-service\venv\lib\site-packages\rest_framework\views.py", line 494, in dispatch
    response = handler(request, *args, **kwargs)
  File "C:\Users\项波\Desktop\flower-service\venv\lib\site-packages\rest_framework\decorators.py", line 50, in handler
    return func(*args, **kwargs)
  File "C:\Users\项波\Desktop\flower-service\src\apps\index\apis.py", line 12, in index_img
    index_imgs = IndexImg.objects.filter_not_deleted()
AttributeError: 'Manager' object has no attribute 'filter_not_deleted'
2019-09-01 15:38:03,506 [Thread-2:976] [service_mart.common.decorator:52] [ERROR]- error:error response:'Manager' object has no attribute 'filter_not_deleted'
2019-09-01 15:38:03,508 [Thread-2:976] [service_mart.helper.middleware:163] [ERROR]- {{{
Traceback (most recent call last):

  File "C:\Users\项波\Desktop\flower-service\venv\lib\site-packages\django\core\handlers\base.py", line 113, in _get_response
    response = wrapped_callback(request, *callback_args, **callback_kwargs)

  File "C:\Users\项波\Desktop\flower-service\src\apps\common\decorator.py", line 17, in _func
    resp = func(*args, **kwargs)

  File "C:\Users\项波\Desktop\flower-service\venv\lib\site-packages\django\views\decorators\csrf.py", line 54, in wrapped_view
    return view_func(*args, **kwargs)

  File "C:\Users\项波\Desktop\flower-service\venv\lib\site-packages\django\views\generic\base.py", line 71, in view
    return self.dispatch(request, *args, **kwargs)

  File "C:\Users\项波\Desktop\flower-service\venv\lib\site-packages\rest_framework\views.py", line 497, in dispatch
    response = self.handle_exception(exc)

  File "C:\Users\项波\Desktop\flower-service\venv\lib\site-packages\rest_framework\views.py", line 457, in handle_exception
    self.raise_uncaught_exception(exc)

  File "C:\Users\项波\Desktop\flower-service\venv\lib\site-packages\rest_framework\views.py", line 468, in raise_uncaught_exception
    raise exc

  File "C:\Users\项波\Desktop\flower-service\venv\lib\site-packages\rest_framework\views.py", line 494, in dispatch
    response = handler(request, *args, **kwargs)

  File "C:\Users\项波\Desktop\flower-service\venv\lib\site-packages\rest_framework\decorators.py", line 50, in handler
    return func(*args, **kwargs)

  File "C:\Users\项波\Desktop\flower-service\src\apps\index\apis.py", line 12, in index_img
    index_imgs = IndexImg.objects.filter_not_deleted()

AttributeError: 'Manager' object has no attribute 'filter_not_deleted'

}}}

{{{
<WSGIRequest: GET '/api/index/indexImg/'>
}}}
Traceback (most recent call last):
  File "C:\Users\项波\Desktop\flower-service\venv\lib\site-packages\django\core\handlers\base.py", line 113, in _get_response
    response = wrapped_callback(request, *callback_args, **callback_kwargs)
  File "C:\Users\项波\Desktop\flower-service\src\apps\common\decorator.py", line 17, in _func
    resp = func(*args, **kwargs)
  File "C:\Users\项波\Desktop\flower-service\venv\lib\site-packages\django\views\decorators\csrf.py", line 54, in wrapped_view
    return view_func(*args, **kwargs)
  File "C:\Users\项波\Desktop\flower-service\venv\lib\site-packages\django\views\generic\base.py", line 71, in view
    return self.dispatch(request, *args, **kwargs)
  File "C:\Users\项波\Desktop\flower-service\venv\lib\site-packages\rest_framework\views.py", line 497, in dispatch
    response = self.handle_exception(exc)
  File "C:\Users\项波\Desktop\flower-service\venv\lib\site-packages\rest_framework\views.py", line 457, in handle_exception
    self.raise_uncaught_exception(exc)
  File "C:\Users\项波\Desktop\flower-service\venv\lib\site-packages\rest_framework\views.py", line 468, in raise_uncaught_exception
    raise exc
  File "C:\Users\项波\Desktop\flower-service\venv\lib\site-packages\rest_framework\views.py", line 494, in dispatch
    response = handler(request, *args, **kwargs)
  File "C:\Users\项波\Desktop\flower-service\venv\lib\site-packages\rest_framework\decorators.py", line 50, in handler
    return func(*args, **kwargs)
  File "C:\Users\项波\Desktop\flower-service\src\apps\index\apis.py", line 12, in index_img
    index_imgs = IndexImg.objects.filter_not_deleted()
AttributeError: 'Manager' object has no attribute 'filter_not_deleted'
2019-09-01 15:38:12,154 [Thread-2:3788] [service_mart.common.decorator:52] [ERROR]- error:error response:'Manager' object has no attribute 'filter_not_deleted'
2019-09-01 15:38:12,156 [Thread-2:3788] [service_mart.helper.middleware:163] [ERROR]- {{{
Traceback (most recent call last):

  File "C:\Users\项波\Desktop\flower-service\venv\lib\site-packages\django\core\handlers\base.py", line 113, in _get_response
    response = wrapped_callback(request, *callback_args, **callback_kwargs)

  File "C:\Users\项波\Desktop\flower-service\src\apps\common\decorator.py", line 17, in _func
    resp = func(*args, **kwargs)

  File "C:\Users\项波\Desktop\flower-service\venv\lib\site-packages\django\views\decorators\csrf.py", line 54, in wrapped_view
    return view_func(*args, **kwargs)

  File "C:\Users\项波\Desktop\flower-service\venv\lib\site-packages\django\views\generic\base.py", line 71, in view
    return self.dispatch(request, *args, **kwargs)

  File "C:\Users\项波\Desktop\flower-service\venv\lib\site-packages\rest_framework\views.py", line 497, in dispatch
    response = self.handle_exception(exc)

  File "C:\Users\项波\Desktop\flower-service\venv\lib\site-packages\rest_framework\views.py", line 457, in handle_exception
    self.raise_uncaught_exception(exc)

  File "C:\Users\项波\Desktop\flower-service\venv\lib\site-packages\rest_framework\views.py", line 468, in raise_uncaught_exception
    raise exc

  File "C:\Users\项波\Desktop\flower-service\venv\lib\site-packages\rest_framework\views.py", line 494, in dispatch
    response = handler(request, *args, **kwargs)

  File "C:\Users\项波\Desktop\flower-service\venv\lib\site-packages\rest_framework\decorators.py", line 50, in handler
    return func(*args, **kwargs)

  File "C:\Users\项波\Desktop\flower-service\src\apps\index\apis.py", line 12, in index_img
    index_imgs = IndexImg.objects.filter_not_deleted()

AttributeError: 'Manager' object has no attribute 'filter_not_deleted'

}}}

{{{
<WSGIRequest: GET '/api/index/indexImg/'>
}}}
Traceback (most recent call last):
  File "C:\Users\项波\Desktop\flower-service\venv\lib\site-packages\django\core\handlers\base.py", line 113, in _get_response
    response = wrapped_callback(request, *callback_args, **callback_kwargs)
  File "C:\Users\项波\Desktop\flower-service\src\apps\common\decorator.py", line 17, in _func
    resp = func(*args, **kwargs)
  File "C:\Users\项波\Desktop\flower-service\venv\lib\site-packages\django\views\decorators\csrf.py", line 54, in wrapped_view
    return view_func(*args, **kwargs)
  File "C:\Users\项波\Desktop\flower-service\venv\lib\site-packages\django\views\generic\base.py", line 71, in view
    return self.dispatch(request, *args, **kwargs)
  File "C:\Users\项波\Desktop\flower-service\venv\lib\site-packages\rest_framework\views.py", line 497, in dispatch
    response = self.handle_exception(exc)
  File "C:\Users\项波\Desktop\flower-service\venv\lib\site-packages\rest_framework\views.py", line 457, in handle_exception
    self.raise_uncaught_exception(exc)
  File "C:\Users\项波\Desktop\flower-service\venv\lib\site-packages\rest_framework\views.py", line 468, in raise_uncaught_exception
    raise exc
  File "C:\Users\项波\Desktop\flower-service\venv\lib\site-packages\rest_framework\views.py", line 494, in dispatch
    response = handler(request, *args, **kwargs)
  File "C:\Users\项波\Desktop\flower-service\venv\lib\site-packages\rest_framework\decorators.py", line 50, in handler
    return func(*args, **kwargs)
  File "C:\Users\项波\Desktop\flower-service\src\apps\index\apis.py", line 12, in index_img
    index_imgs = IndexImg.objects.filter_not_deleted()
AttributeError: 'Manager' object has no attribute 'filter_not_deleted'
2019-09-01 15:38:32,702 [Thread-1:5328] [service_mart.common.decorator:52] [ERROR]- error:error response:filter_not_deleted() missing 1 required positional argument: 'self'
2019-09-01 15:38:32,705 [Thread-1:5328] [service_mart.helper.middleware:163] [ERROR]- {{{
Traceback (most recent call last):

  File "C:\Users\项波\Desktop\flower-service\venv\lib\site-packages\django\core\handlers\base.py", line 113, in _get_response
    response = wrapped_callback(request, *callback_args, **callback_kwargs)

  File "C:\Users\项波\Desktop\flower-service\src\apps\common\decorator.py", line 17, in _func
    resp = func(*args, **kwargs)

  File "C:\Users\项波\Desktop\flower-service\venv\lib\site-packages\django\views\decorators\csrf.py", line 54, in wrapped_view
    return view_func(*args, **kwargs)

  File "C:\Users\项波\Desktop\flower-service\venv\lib\site-packages\django\views\generic\base.py", line 71, in view
    return self.dispatch(request, *args, **kwargs)

  File "C:\Users\项波\Desktop\flower-service\venv\lib\site-packages\rest_framework\views.py", line 497, in dispatch
    response = self.handle_exception(exc)

  File "C:\Users\项波\Desktop\flower-service\venv\lib\site-packages\rest_framework\views.py", line 457, in handle_exception
    self.raise_uncaught_exception(exc)

  File "C:\Users\项波\Desktop\flower-service\venv\lib\site-packages\rest_framework\views.py", line 468, in raise_uncaught_exception
    raise exc

  File "C:\Users\项波\Desktop\flower-service\venv\lib\site-packages\rest_framework\views.py", line 494, in dispatch
    response = handler(request, *args, **kwargs)

  File "C:\Users\项波\Desktop\flower-service\venv\lib\site-packages\rest_framework\decorators.py", line 50, in handler
    return func(*args, **kwargs)

  File "C:\Users\项波\Desktop\flower-service\src\apps\index\apis.py", line 12, in index_img
    index_imgs = IndexImg.filter_not_deleted()

TypeError: filter_not_deleted() missing 1 required positional argument: 'self'

}}}

{{{
<WSGIRequest: GET '/api/index/indexImg/'>
}}}
Traceback (most recent call last):
  File "C:\Users\项波\Desktop\flower-service\venv\lib\site-packages\django\core\handlers\base.py", line 113, in _get_response
    response = wrapped_callback(request, *callback_args, **callback_kwargs)
  File "C:\Users\项波\Desktop\flower-service\src\apps\common\decorator.py", line 17, in _func
    resp = func(*args, **kwargs)
  File "C:\Users\项波\Desktop\flower-service\venv\lib\site-packages\django\views\decorators\csrf.py", line 54, in wrapped_view
    return view_func(*args, **kwargs)
  File "C:\Users\项波\Desktop\flower-service\venv\lib\site-packages\django\views\generic\base.py", line 71, in view
    return self.dispatch(request, *args, **kwargs)
  File "C:\Users\项波\Desktop\flower-service\venv\lib\site-packages\rest_framework\views.py", line 497, in dispatch
    response = self.handle_exception(exc)
  File "C:\Users\项波\Desktop\flower-service\venv\lib\site-packages\rest_framework\views.py", line 457, in handle_exception
    self.raise_uncaught_exception(exc)
  File "C:\Users\项波\Desktop\flower-service\venv\lib\site-packages\rest_framework\views.py", line 468, in raise_uncaught_exception
    raise exc
  File "C:\Users\项波\Desktop\flower-service\venv\lib\site-packages\rest_framework\views.py", line 494, in dispatch
    response = handler(request, *args, **kwargs)
  File "C:\Users\项波\Desktop\flower-service\venv\lib\site-packages\rest_framework\decorators.py", line 50, in handler
    return func(*args, **kwargs)
  File "C:\Users\项波\Desktop\flower-service\src\apps\index\apis.py", line 12, in index_img
    index_imgs = IndexImg.filter_not_deleted()
TypeError: filter_not_deleted() missing 1 required positional argument: 'self'
2019-09-01 15:38:51,487 [Thread-1:11480] [service_mart.common.decorator:52] [ERROR]- error:error response:'Manager' object has no attribute 'filter_not_deleted'
2019-09-01 15:38:51,491 [Thread-1:11480] [service_mart.helper.middleware:163] [ERROR]- {{{
Traceback (most recent call last):

  File "C:\Users\项波\Desktop\flower-service\venv\lib\site-packages\django\core\handlers\base.py", line 113, in _get_response
    response = wrapped_callback(request, *callback_args, **callback_kwargs)

  File "C:\Users\项波\Desktop\flower-service\src\apps\common\decorator.py", line 17, in _func
    resp = func(*args, **kwargs)

  File "C:\Users\项波\Desktop\flower-service\venv\lib\site-packages\django\views\decorators\csrf.py", line 54, in wrapped_view
    return view_func(*args, **kwargs)

  File "C:\Users\项波\Desktop\flower-service\venv\lib\site-packages\django\views\generic\base.py", line 71, in view
    return self.dispatch(request, *args, **kwargs)

  File "C:\Users\项波\Desktop\flower-service\venv\lib\site-packages\rest_framework\views.py", line 497, in dispatch
    response = self.handle_exception(exc)

  File "C:\Users\项波\Desktop\flower-service\venv\lib\site-packages\rest_framework\views.py", line 457, in handle_exception
    self.raise_uncaught_exception(exc)

  File "C:\Users\项波\Desktop\flower-service\venv\lib\site-packages\rest_framework\views.py", line 468, in raise_uncaught_exception
    raise exc

  File "C:\Users\项波\Desktop\flower-service\venv\lib\site-packages\rest_framework\views.py", line 494, in dispatch
    response = handler(request, *args, **kwargs)

  File "C:\Users\项波\Desktop\flower-service\venv\lib\site-packages\rest_framework\decorators.py", line 50, in handler
    return func(*args, **kwargs)

  File "C:\Users\项波\Desktop\flower-service\src\apps\index\apis.py", line 12, in index_img
    index_imgs = IndexImg.objects   .filter_not_deleted()

AttributeError: 'Manager' object has no attribute 'filter_not_deleted'

}}}

{{{
<WSGIRequest: GET '/api/index/indexImg/'>
}}}
Traceback (most recent call last):
  File "C:\Users\项波\Desktop\flower-service\venv\lib\site-packages\django\core\handlers\base.py", line 113, in _get_response
    response = wrapped_callback(request, *callback_args, **callback_kwargs)
  File "C:\Users\项波\Desktop\flower-service\src\apps\common\decorator.py", line 17, in _func
    resp = func(*args, **kwargs)
  File "C:\Users\项波\Desktop\flower-service\venv\lib\site-packages\django\views\decorators\csrf.py", line 54, in wrapped_view
    return view_func(*args, **kwargs)
  File "C:\Users\项波\Desktop\flower-service\venv\lib\site-packages\django\views\generic\base.py", line 71, in view
    return self.dispatch(request, *args, **kwargs)
  File "C:\Users\项波\Desktop\flower-service\venv\lib\site-packages\rest_framework\views.py", line 497, in dispatch
    response = self.handle_exception(exc)
  File "C:\Users\项波\Desktop\flower-service\venv\lib\site-packages\rest_framework\views.py", line 457, in handle_exception
    self.raise_uncaught_exception(exc)
  File "C:\Users\项波\Desktop\flower-service\venv\lib\site-packages\rest_framework\views.py", line 468, in raise_uncaught_exception
    raise exc
  File "C:\Users\项波\Desktop\flower-service\venv\lib\site-packages\rest_framework\views.py", line 494, in dispatch
    response = handler(request, *args, **kwargs)
  File "C:\Users\项波\Desktop\flower-service\venv\lib\site-packages\rest_framework\decorators.py", line 50, in handler
    return func(*args, **kwargs)
  File "C:\Users\项波\Desktop\flower-service\src\apps\index\apis.py", line 12, in index_img
    index_imgs = IndexImg.objects   .filter_not_deleted()
AttributeError: 'Manager' object has no attribute 'filter_not_deleted'
2019-09-01 15:39:06,554 [Thread-1:2028] [service_mart.common.decorator:52] [ERROR]- error:error response:'Manager' object has no attribute 'filter_not_deleted'
2019-09-01 15:39:06,556 [Thread-1:2028] [service_mart.helper.middleware:163] [ERROR]- {{{
Traceback (most recent call last):

  File "C:\Users\项波\Desktop\flower-service\venv\lib\site-packages\django\core\handlers\base.py", line 113, in _get_response
    response = wrapped_callback(request, *callback_args, **callback_kwargs)

  File "C:\Users\项波\Desktop\flower-service\src\apps\common\decorator.py", line 17, in _func
    resp = func(*args, **kwargs)

  File "C:\Users\项波\Desktop\flower-service\venv\lib\site-packages\django\views\decorators\csrf.py", line 54, in wrapped_view
    return view_func(*args, **kwargs)

  File "C:\Users\项波\Desktop\flower-service\venv\lib\site-packages\django\views\generic\base.py", line 71, in view
    return self.dispatch(request, *args, **kwargs)

  File "C:\Users\项波\Desktop\flower-service\venv\lib\site-packages\rest_framework\views.py", line 497, in dispatch
    response = self.handle_exception(exc)

  File "C:\Users\项波\Desktop\flower-service\venv\lib\site-packages\rest_framework\views.py", line 457, in handle_exception
    self.raise_uncaught_exception(exc)

  File "C:\Users\项波\Desktop\flower-service\venv\lib\site-packages\rest_framework\views.py", line 468, in raise_uncaught_exception
    raise exc

  File "C:\Users\项波\Desktop\flower-service\venv\lib\site-packages\rest_framework\views.py", line 494, in dispatch
    response = handler(request, *args, **kwargs)

  File "C:\Users\项波\Desktop\flower-service\venv\lib\site-packages\rest_framework\decorators.py", line 50, in handler
    return func(*args, **kwargs)

  File "C:\Users\项波\Desktop\flower-service\src\apps\index\apis.py", line 12, in index_img
    index_imgs = IndexImg.objects.filter_not_deleted()

AttributeError: 'Manager' object has no attribute 'filter_not_deleted'

}}}

{{{
<WSGIRequest: GET '/api/index/indexImg/'>
}}}
Traceback (most recent call last):
  File "C:\Users\项波\Desktop\flower-service\venv\lib\site-packages\django\core\handlers\base.py", line 113, in _get_response
    response = wrapped_callback(request, *callback_args, **callback_kwargs)
  File "C:\Users\项波\Desktop\flower-service\src\apps\common\decorator.py", line 17, in _func
    resp = func(*args, **kwargs)
  File "C:\Users\项波\Desktop\flower-service\venv\lib\site-packages\django\views\decorators\csrf.py", line 54, in wrapped_view
    return view_func(*args, **kwargs)
  File "C:\Users\项波\Desktop\flower-service\venv\lib\site-packages\django\views\generic\base.py", line 71, in view
    return self.dispatch(request, *args, **kwargs)
  File "C:\Users\项波\Desktop\flower-service\venv\lib\site-packages\rest_framework\views.py", line 497, in dispatch
    response = self.handle_exception(exc)
  File "C:\Users\项波\Desktop\flower-service\venv\lib\site-packages\rest_framework\views.py", line 457, in handle_exception
    self.raise_uncaught_exception(exc)
  File "C:\Users\项波\Desktop\flower-service\venv\lib\site-packages\rest_framework\views.py", line 468, in raise_uncaught_exception
    raise exc
  File "C:\Users\项波\Desktop\flower-service\venv\lib\site-packages\rest_framework\views.py", line 494, in dispatch
    response = handler(request, *args, **kwargs)
  File "C:\Users\项波\Desktop\flower-service\venv\lib\site-packages\rest_framework\decorators.py", line 50, in handler
    return func(*args, **kwargs)
  File "C:\Users\项波\Desktop\flower-service\src\apps\index\apis.py", line 12, in index_img
    index_imgs = IndexImg.objects.filter_not_deleted()
AttributeError: 'Manager' object has no attribute 'filter_not_deleted'
2019-09-01 15:41:06,868 [Thread-1:192] [service_mart.common.decorator:52] [ERROR]- error:error response:IndexImg() got an unexpected keyword argument 'model'
2019-09-01 15:41:06,872 [Thread-1:192] [service_mart.helper.middleware:163] [ERROR]- {{{
Traceback (most recent call last):

  File "C:\Users\项波\Desktop\flower-service\venv\lib\site-packages\django\core\handlers\base.py", line 113, in _get_response
    response = wrapped_callback(request, *callback_args, **callback_kwargs)

  File "C:\Users\项波\Desktop\flower-service\src\apps\common\decorator.py", line 17, in _func
    resp = func(*args, **kwargs)

  File "C:\Users\项波\Desktop\flower-service\venv\lib\site-packages\django\views\decorators\csrf.py", line 54, in wrapped_view
    return view_func(*args, **kwargs)

  File "C:\Users\项波\Desktop\flower-service\venv\lib\site-packages\django\views\generic\base.py", line 71, in view
    return self.dispatch(request, *args, **kwargs)

  File "C:\Users\项波\Desktop\flower-service\venv\lib\site-packages\rest_framework\views.py", line 497, in dispatch
    response = self.handle_exception(exc)

  File "C:\Users\项波\Desktop\flower-service\venv\lib\site-packages\rest_framework\views.py", line 457, in handle_exception
    self.raise_uncaught_exception(exc)

  File "C:\Users\项波\Desktop\flower-service\venv\lib\site-packages\rest_framework\views.py", line 468, in raise_uncaught_exception
    raise exc

  File "C:\Users\项波\Desktop\flower-service\venv\lib\site-packages\rest_framework\views.py", line 494, in dispatch
    response = handler(request, *args, **kwargs)

  File "C:\Users\项波\Desktop\flower-service\venv\lib\site-packages\rest_framework\decorators.py", line 50, in handler
    return func(*args, **kwargs)

  File "C:\Users\项波\Desktop\flower-service\src\apps\index\apis.py", line 12, in index_img
    index_imgs = IndexImg().filter_not_deleted()

  File "C:\Users\项波\Desktop\flower-service\src\apps\common\models.py", line 22, in filter_not_deleted
    return self.filter(delete_status=DeleteStatusMixin.STATUS_NOT_DELETED)

  File "C:\Users\项波\Desktop\flower-service\venv\lib\site-packages\django\db\models\query.py", line 892, in filter
    return self._filter_or_exclude(False, *args, **kwargs)

  File "C:\Users\项波\Desktop\flower-service\venv\lib\site-packages\django\db\models\query.py", line 906, in _filter_or_exclude
    clone = self._chain()

  File "C:\Users\项波\Desktop\flower-service\venv\lib\site-packages\django\db\models\query.py", line 1219, in _chain
    obj = self._clone()

  File "C:\Users\项波\Desktop\flower-service\venv\lib\site-packages\django\db\models\query.py", line 1231, in _clone
    c = self.__class__(model=self.model, query=self.query.chain(), using=self._db, hints=self._hints)

  File "C:\Users\项波\Desktop\flower-service\venv\lib\site-packages\django\db\models\base.py", line 501, in __init__
    raise TypeError("%s() got an unexpected keyword argument '%s'" % (cls.__name__, kwarg))

TypeError: IndexImg() got an unexpected keyword argument 'model'

}}}

{{{
<WSGIRequest: GET '/api/index/indexImg/'>
}}}
Traceback (most recent call last):
  File "C:\Users\项波\Desktop\flower-service\venv\lib\site-packages\django\core\handlers\base.py", line 113, in _get_response
    response = wrapped_callback(request, *callback_args, **callback_kwargs)
  File "C:\Users\项波\Desktop\flower-service\src\apps\common\decorator.py", line 17, in _func
    resp = func(*args, **kwargs)
  File "C:\Users\项波\Desktop\flower-service\venv\lib\site-packages\django\views\decorators\csrf.py", line 54, in wrapped_view
    return view_func(*args, **kwargs)
  File "C:\Users\项波\Desktop\flower-service\venv\lib\site-packages\django\views\generic\base.py", line 71, in view
    return self.dispatch(request, *args, **kwargs)
  File "C:\Users\项波\Desktop\flower-service\venv\lib\site-packages\rest_framework\views.py", line 497, in dispatch
    response = self.handle_exception(exc)
  File "C:\Users\项波\Desktop\flower-service\venv\lib\site-packages\rest_framework\views.py", line 457, in handle_exception
    self.raise_uncaught_exception(exc)
  File "C:\Users\项波\Desktop\flower-service\venv\lib\site-packages\rest_framework\views.py", line 468, in raise_uncaught_exception
    raise exc
  File "C:\Users\项波\Desktop\flower-service\venv\lib\site-packages\rest_framework\views.py", line 494, in dispatch
    response = handler(request, *args, **kwargs)
  File "C:\Users\项波\Desktop\flower-service\venv\lib\site-packages\rest_framework\decorators.py", line 50, in handler
    return func(*args, **kwargs)
  File "C:\Users\项波\Desktop\flower-service\src\apps\index\apis.py", line 12, in index_img
    index_imgs = IndexImg().filter_not_deleted()
  File "C:\Users\项波\Desktop\flower-service\src\apps\common\models.py", line 22, in filter_not_deleted
    return self.filter(delete_status=DeleteStatusMixin.STATUS_NOT_DELETED)
  File "C:\Users\项波\Desktop\flower-service\venv\lib\site-packages\django\db\models\query.py", line 892, in filter
    return self._filter_or_exclude(False, *args, **kwargs)
  File "C:\Users\项波\Desktop\flower-service\venv\lib\site-packages\django\db\models\query.py", line 906, in _filter_or_exclude
    clone = self._chain()
  File "C:\Users\项波\Desktop\flower-service\venv\lib\site-packages\django\db\models\query.py", line 1219, in _chain
    obj = self._clone()
  File "C:\Users\项波\Desktop\flower-service\venv\lib\site-packages\django\db\models\query.py", line 1231, in _clone
    c = self.__class__(model=self.model, query=self.query.chain(), using=self._db, hints=self._hints)
  File "C:\Users\项波\Desktop\flower-service\venv\lib\site-packages\django\db\models\base.py", line 501, in __init__
    raise TypeError("%s() got an unexpected keyword argument '%s'" % (cls.__name__, kwarg))
TypeError: IndexImg() got an unexpected keyword argument 'model'
2019-09-01 16:18:45,352 [Thread-6:17152] [service_mart.common.decorator:52] [ERROR]- error:error response:module 'rest_framework.settings' has no attribute 'WEAAPP_KEY'
2019-09-01 16:18:45,353 [Thread-6:17152] [service_mart.helper.middleware:163] [ERROR]- {{{
Traceback (most recent call last):

  File "C:\Users\项波\Desktop\flower-service\venv\lib\site-packages\django\core\handlers\base.py", line 113, in _get_response
    response = wrapped_callback(request, *callback_args, **callback_kwargs)

  File "C:\Users\项波\Desktop\flower-service\venv\lib\site-packages\django\views\decorators\csrf.py", line 54, in wrapped_view
    return view_func(*args, **kwargs)

  File "C:\Users\项波\Desktop\flower-service\venv\lib\site-packages\django\views\generic\base.py", line 71, in view
    return self.dispatch(request, *args, **kwargs)

  File "C:\Users\项波\Desktop\flower-service\venv\lib\site-packages\rest_framework\views.py", line 497, in dispatch
    response = self.handle_exception(exc)

  File "C:\Users\项波\Desktop\flower-service\venv\lib\site-packages\rest_framework\views.py", line 457, in handle_exception
    self.raise_uncaught_exception(exc)

  File "C:\Users\项波\Desktop\flower-service\venv\lib\site-packages\rest_framework\views.py", line 468, in raise_uncaught_exception
    raise exc

  File "C:\Users\项波\Desktop\flower-service\venv\lib\site-packages\rest_framework\views.py", line 494, in dispatch
    response = handler(request, *args, **kwargs)

  File "C:\Users\项波\Desktop\flower-service\src\apps\common\decorator.py", line 17, in _func
    resp = func(*args, **kwargs)

  File "C:\Users\项波\Desktop\flower-service\src\apps\account\apis.py", line 29, in post
    'appid': settings.WEAAPP_KEY,

AttributeError: module 'rest_framework.settings' has no attribute 'WEAAPP_KEY'

}}}

{{{
<WSGIRequest: POST '/api/account/login/'>
}}}
Traceback (most recent call last):
  File "C:\Users\项波\Desktop\flower-service\venv\lib\site-packages\django\core\handlers\base.py", line 113, in _get_response
    response = wrapped_callback(request, *callback_args, **callback_kwargs)
  File "C:\Users\项波\Desktop\flower-service\venv\lib\site-packages\django\views\decorators\csrf.py", line 54, in wrapped_view
    return view_func(*args, **kwargs)
  File "C:\Users\项波\Desktop\flower-service\venv\lib\site-packages\django\views\generic\base.py", line 71, in view
    return self.dispatch(request, *args, **kwargs)
  File "C:\Users\项波\Desktop\flower-service\venv\lib\site-packages\rest_framework\views.py", line 497, in dispatch
    response = self.handle_exception(exc)
  File "C:\Users\项波\Desktop\flower-service\venv\lib\site-packages\rest_framework\views.py", line 457, in handle_exception
    self.raise_uncaught_exception(exc)
  File "C:\Users\项波\Desktop\flower-service\venv\lib\site-packages\rest_framework\views.py", line 468, in raise_uncaught_exception
    raise exc
  File "C:\Users\项波\Desktop\flower-service\venv\lib\site-packages\rest_framework\views.py", line 494, in dispatch
    response = handler(request, *args, **kwargs)
  File "C:\Users\项波\Desktop\flower-service\src\apps\common\decorator.py", line 17, in _func
    resp = func(*args, **kwargs)
  File "C:\Users\项波\Desktop\flower-service\src\apps\account\apis.py", line 29, in post
    'appid': settings.WEAAPP_KEY,
AttributeError: module 'rest_framework.settings' has no attribute 'WEAAPP_KEY'
2019-09-01 16:19:46,829 [Thread-1:4488] [service_mart.common.decorator:52] [ERROR]- error:error response:'dict' object has no attribute 'has_key'
2019-09-01 16:19:46,831 [Thread-1:4488] [service_mart.helper.middleware:163] [ERROR]- {{{
Traceback (most recent call last):

  File "C:\Users\项波\Desktop\flower-service\venv\lib\site-packages\django\core\handlers\base.py", line 113, in _get_response
    response = wrapped_callback(request, *callback_args, **callback_kwargs)

  File "C:\Users\项波\Desktop\flower-service\venv\lib\site-packages\django\views\decorators\csrf.py", line 54, in wrapped_view
    return view_func(*args, **kwargs)

  File "C:\Users\项波\Desktop\flower-service\venv\lib\site-packages\django\views\generic\base.py", line 71, in view
    return self.dispatch(request, *args, **kwargs)

  File "C:\Users\项波\Desktop\flower-service\venv\lib\site-packages\rest_framework\views.py", line 497, in dispatch
    response = self.handle_exception(exc)

  File "C:\Users\项波\Desktop\flower-service\venv\lib\site-packages\rest_framework\views.py", line 457, in handle_exception
    self.raise_uncaught_exception(exc)

  File "C:\Users\项波\Desktop\flower-service\venv\lib\site-packages\rest_framework\views.py", line 468, in raise_uncaught_exception
    raise exc

  File "C:\Users\项波\Desktop\flower-service\venv\lib\site-packages\rest_framework\views.py", line 494, in dispatch
    response = handler(request, *args, **kwargs)

  File "C:\Users\项波\Desktop\flower-service\src\apps\common\decorator.py", line 17, in _func
    resp = func(*args, **kwargs)

  File "C:\Users\项波\Desktop\flower-service\src\apps\account\apis.py", line 42, in post
    if request.META.has_key('HTTP_X_FORWARDED_FOR'):

AttributeError: 'dict' object has no attribute 'has_key'

}}}

{{{
<WSGIRequest: POST '/api/account/login/'>
}}}
Traceback (most recent call last):
  File "C:\Users\项波\Desktop\flower-service\venv\lib\site-packages\django\core\handlers\base.py", line 113, in _get_response
    response = wrapped_callback(request, *callback_args, **callback_kwargs)
  File "C:\Users\项波\Desktop\flower-service\venv\lib\site-packages\django\views\decorators\csrf.py", line 54, in wrapped_view
    return view_func(*args, **kwargs)
  File "C:\Users\项波\Desktop\flower-service\venv\lib\site-packages\django\views\generic\base.py", line 71, in view
    return self.dispatch(request, *args, **kwargs)
  File "C:\Users\项波\Desktop\flower-service\venv\lib\site-packages\rest_framework\views.py", line 497, in dispatch
    response = self.handle_exception(exc)
  File "C:\Users\项波\Desktop\flower-service\venv\lib\site-packages\rest_framework\views.py", line 457, in handle_exception
    self.raise_uncaught_exception(exc)
  File "C:\Users\项波\Desktop\flower-service\venv\lib\site-packages\rest_framework\views.py", line 468, in raise_uncaught_exception
    raise exc
  File "C:\Users\项波\Desktop\flower-service\venv\lib\site-packages\rest_framework\views.py", line 494, in dispatch
    response = handler(request, *args, **kwargs)
  File "C:\Users\项波\Desktop\flower-service\src\apps\common\decorator.py", line 17, in _func
    resp = func(*args, **kwargs)
  File "C:\Users\项波\Desktop\flower-service\src\apps\account\apis.py", line 42, in post
    if request.META.has_key('HTTP_X_FORWARDED_FOR'):
AttributeError: 'dict' object has no attribute 'has_key'
2019-09-01 16:21:20,090 [Thread-1:3140] [service_mart.common.decorator:52] [ERROR]- error:error response:'dict' object has no attribute 'has_key'
2019-09-01 16:21:20,092 [Thread-1:3140] [service_mart.helper.middleware:163] [ERROR]- {{{
Traceback (most recent call last):

  File "C:\Users\项波\Desktop\flower-service\venv\lib\site-packages\django\core\handlers\base.py", line 113, in _get_response
    response = wrapped_callback(request, *callback_args, **callback_kwargs)

  File "C:\Users\项波\Desktop\flower-service\venv\lib\site-packages\django\views\decorators\csrf.py", line 54, in wrapped_view
    return view_func(*args, **kwargs)

  File "C:\Users\项波\Desktop\flower-service\venv\lib\site-packages\django\views\generic\base.py", line 71, in view
    return self.dispatch(request, *args, **kwargs)

  File "C:\Users\项波\Desktop\flower-service\venv\lib\site-packages\rest_framework\views.py", line 497, in dispatch
    response = self.handle_exception(exc)

  File "C:\Users\项波\Desktop\flower-service\venv\lib\site-packages\rest_framework\views.py", line 457, in handle_exception
    self.raise_uncaught_exception(exc)

  File "C:\Users\项波\Desktop\flower-service\venv\lib\site-packages\rest_framework\views.py", line 468, in raise_uncaught_exception
    raise exc

  File "C:\Users\项波\Desktop\flower-service\venv\lib\site-packages\rest_framework\views.py", line 494, in dispatch
    response = handler(request, *args, **kwargs)

  File "C:\Users\项波\Desktop\flower-service\src\apps\common\decorator.py", line 17, in _func
    resp = func(*args, **kwargs)

  File "C:\Users\项波\Desktop\flower-service\src\apps\account\apis.py", line 43, in post
    if request.META.has_key('HTTP_X_FORWARDED_FOR'):

AttributeError: 'dict' object has no attribute 'has_key'

}}}

{{{
<WSGIRequest: POST '/api/account/login/'>
}}}
Traceback (most recent call last):
  File "C:\Users\项波\Desktop\flower-service\venv\lib\site-packages\django\core\handlers\base.py", line 113, in _get_response
    response = wrapped_callback(request, *callback_args, **callback_kwargs)
  File "C:\Users\项波\Desktop\flower-service\venv\lib\site-packages\django\views\decorators\csrf.py", line 54, in wrapped_view
    return view_func(*args, **kwargs)
  File "C:\Users\项波\Desktop\flower-service\venv\lib\site-packages\django\views\generic\base.py", line 71, in view
    return self.dispatch(request, *args, **kwargs)
  File "C:\Users\项波\Desktop\flower-service\venv\lib\site-packages\rest_framework\views.py", line 497, in dispatch
    response = self.handle_exception(exc)
  File "C:\Users\项波\Desktop\flower-service\venv\lib\site-packages\rest_framework\views.py", line 457, in handle_exception
    self.raise_uncaught_exception(exc)
  File "C:\Users\项波\Desktop\flower-service\venv\lib\site-packages\rest_framework\views.py", line 468, in raise_uncaught_exception
    raise exc
  File "C:\Users\项波\Desktop\flower-service\venv\lib\site-packages\rest_framework\views.py", line 494, in dispatch
    response = handler(request, *args, **kwargs)
  File "C:\Users\项波\Desktop\flower-service\src\apps\common\decorator.py", line 17, in _func
    resp = func(*args, **kwargs)
  File "C:\Users\项波\Desktop\flower-service\src\apps\account\apis.py", line 43, in post
    if request.META.has_key('HTTP_X_FORWARDED_FOR'):
AttributeError: 'dict' object has no attribute 'has_key'
2019-09-01 16:25:52,908 [Thread-1:9924] [service_mart.common.decorator:52] [ERROR]- error:error response:Manager isn't accessible via MyUser instances
2019-09-01 16:25:52,910 [Thread-1:9924] [service_mart.helper.middleware:163] [ERROR]- {{{
Traceback (most recent call last):

  File "C:\Users\项波\Desktop\flower-service\venv\lib\site-packages\django\core\handlers\base.py", line 113, in _get_response
    response = wrapped_callback(request, *callback_args, **callback_kwargs)

  File "C:\Users\项波\Desktop\flower-service\venv\lib\site-packages\django\views\decorators\csrf.py", line 54, in wrapped_view
    return view_func(*args, **kwargs)

  File "C:\Users\项波\Desktop\flower-service\venv\lib\site-packages\django\views\generic\base.py", line 71, in view
    return self.dispatch(request, *args, **kwargs)

  File "C:\Users\项波\Desktop\flower-service\venv\lib\site-packages\rest_framework\views.py", line 497, in dispatch
    response = self.handle_exception(exc)

  File "C:\Users\项波\Desktop\flower-service\venv\lib\site-packages\rest_framework\views.py", line 457, in handle_exception
    self.raise_uncaught_exception(exc)

  File "C:\Users\项波\Desktop\flower-service\venv\lib\site-packages\rest_framework\views.py", line 468, in raise_uncaught_exception
    raise exc

  File "C:\Users\项波\Desktop\flower-service\venv\lib\site-packages\rest_framework\views.py", line 494, in dispatch
    response = handler(request, *args, **kwargs)

  File "C:\Users\项波\Desktop\flower-service\src\apps\common\decorator.py", line 17, in _func
    resp = func(*args, **kwargs)

  File "C:\Users\项波\Desktop\flower-service\src\apps\account\apis.py", line 56, in post
    user.objects.update(user_regip=user_ip)

  File "C:\Users\项波\Desktop\flower-service\venv\lib\site-packages\django\db\models\manager.py", line 176, in __get__
    raise AttributeError("Manager isn't accessible via %s instances" % cls.__name__)

AttributeError: Manager isn't accessible via MyUser instances

}}}

{{{
<WSGIRequest: POST '/api/account/login/'>
}}}
Traceback (most recent call last):
  File "C:\Users\项波\Desktop\flower-service\venv\lib\site-packages\django\core\handlers\base.py", line 113, in _get_response
    response = wrapped_callback(request, *callback_args, **callback_kwargs)
  File "C:\Users\项波\Desktop\flower-service\venv\lib\site-packages\django\views\decorators\csrf.py", line 54, in wrapped_view
    return view_func(*args, **kwargs)
  File "C:\Users\项波\Desktop\flower-service\venv\lib\site-packages\django\views\generic\base.py", line 71, in view
    return self.dispatch(request, *args, **kwargs)
  File "C:\Users\项波\Desktop\flower-service\venv\lib\site-packages\rest_framework\views.py", line 497, in dispatch
    response = self.handle_exception(exc)
  File "C:\Users\项波\Desktop\flower-service\venv\lib\site-packages\rest_framework\views.py", line 457, in handle_exception
    self.raise_uncaught_exception(exc)
  File "C:\Users\项波\Desktop\flower-service\venv\lib\site-packages\rest_framework\views.py", line 468, in raise_uncaught_exception
    raise exc
  File "C:\Users\项波\Desktop\flower-service\venv\lib\site-packages\rest_framework\views.py", line 494, in dispatch
    response = handler(request, *args, **kwargs)
  File "C:\Users\项波\Desktop\flower-service\src\apps\common\decorator.py", line 17, in _func
    resp = func(*args, **kwargs)
  File "C:\Users\项波\Desktop\flower-service\src\apps\account\apis.py", line 56, in post
    user.objects.update(user_regip=user_ip)
  File "C:\Users\项波\Desktop\flower-service\venv\lib\site-packages\django\db\models\manager.py", line 176, in __get__
    raise AttributeError("Manager isn't accessible via %s instances" % cls.__name__)
AttributeError: Manager isn't accessible via MyUser instances
2019-09-01 16:32:18,893 [Thread-3:5068] [service_mart.common.decorator:52] [ERROR]- error:error response:Manager isn't accessible via MyUser instances
2019-09-01 16:32:18,896 [Thread-3:5068] [service_mart.helper.middleware:163] [ERROR]- {{{
Traceback (most recent call last):

  File "C:\Users\项波\Desktop\flower-service\venv\lib\site-packages\django\core\handlers\base.py", line 113, in _get_response
    response = wrapped_callback(request, *callback_args, **callback_kwargs)

  File "C:\Users\项波\Desktop\flower-service\venv\lib\site-packages\django\views\decorators\csrf.py", line 54, in wrapped_view
    return view_func(*args, **kwargs)

  File "C:\Users\项波\Desktop\flower-service\venv\lib\site-packages\django\views\generic\base.py", line 71, in view
    return self.dispatch(request, *args, **kwargs)

  File "C:\Users\项波\Desktop\flower-service\venv\lib\site-packages\rest_framework\views.py", line 497, in dispatch
    response = self.handle_exception(exc)

  File "C:\Users\项波\Desktop\flower-service\venv\lib\site-packages\rest_framework\views.py", line 457, in handle_exception
    self.raise_uncaught_exception(exc)

  File "C:\Users\项波\Desktop\flower-service\venv\lib\site-packages\rest_framework\views.py", line 468, in raise_uncaught_exception
    raise exc

  File "C:\Users\项波\Desktop\flower-service\venv\lib\site-packages\rest_framework\views.py", line 494, in dispatch
    response = handler(request, *args, **kwargs)

  File "C:\Users\项波\Desktop\flower-service\src\apps\common\decorator.py", line 17, in _func
    resp = func(*args, **kwargs)

  File "C:\Users\项波\Desktop\flower-service\src\apps\account\apis.py", line 56, in post
    user.objects.update(user_regip=user_ip)

  File "C:\Users\项波\Desktop\flower-service\venv\lib\site-packages\django\db\models\manager.py", line 176, in __get__
    raise AttributeError("Manager isn't accessible via %s instances" % cls.__name__)

AttributeError: Manager isn't accessible via MyUser instances

}}}

{{{
<WSGIRequest: POST '/api/account/login/'>
}}}
Traceback (most recent call last):
  File "C:\Users\项波\Desktop\flower-service\venv\lib\site-packages\django\core\handlers\base.py", line 113, in _get_response
    response = wrapped_callback(request, *callback_args, **callback_kwargs)
  File "C:\Users\项波\Desktop\flower-service\venv\lib\site-packages\django\views\decorators\csrf.py", line 54, in wrapped_view
    return view_func(*args, **kwargs)
  File "C:\Users\项波\Desktop\flower-service\venv\lib\site-packages\django\views\generic\base.py", line 71, in view
    return self.dispatch(request, *args, **kwargs)
  File "C:\Users\项波\Desktop\flower-service\venv\lib\site-packages\rest_framework\views.py", line 497, in dispatch
    response = self.handle_exception(exc)
  File "C:\Users\项波\Desktop\flower-service\venv\lib\site-packages\rest_framework\views.py", line 457, in handle_exception
    self.raise_uncaught_exception(exc)
  File "C:\Users\项波\Desktop\flower-service\venv\lib\site-packages\rest_framework\views.py", line 468, in raise_uncaught_exception
    raise exc
  File "C:\Users\项波\Desktop\flower-service\venv\lib\site-packages\rest_framework\views.py", line 494, in dispatch
    response = handler(request, *args, **kwargs)
  File "C:\Users\项波\Desktop\flower-service\src\apps\common\decorator.py", line 17, in _func
    resp = func(*args, **kwargs)
  File "C:\Users\项波\Desktop\flower-service\src\apps\account\apis.py", line 56, in post
    user.objects.update(user_regip=user_ip)
  File "C:\Users\项波\Desktop\flower-service\venv\lib\site-packages\django\db\models\manager.py", line 176, in __get__
    raise AttributeError("Manager isn't accessible via %s instances" % cls.__name__)
AttributeError: Manager isn't accessible via MyUser instances
2019-09-01 16:51:26,613 [Thread-5:17144] [service_mart.common.decorator:52] [ERROR]- error:error response:'MyUser' object has no attribute 'update'
2019-09-01 16:51:26,614 [Thread-5:17144] [service_mart.helper.middleware:163] [ERROR]- {{{
Traceback (most recent call last):

  File "C:\Users\项波\Desktop\flower-service\venv\lib\site-packages\django\core\handlers\base.py", line 113, in _get_response
    response = wrapped_callback(request, *callback_args, **callback_kwargs)

  File "C:\Users\项波\Desktop\flower-service\venv\lib\site-packages\django\views\decorators\csrf.py", line 54, in wrapped_view
    return view_func(*args, **kwargs)

  File "C:\Users\项波\Desktop\flower-service\venv\lib\site-packages\django\views\generic\base.py", line 71, in view
    return self.dispatch(request, *args, **kwargs)

  File "C:\Users\项波\Desktop\flower-service\venv\lib\site-packages\rest_framework\views.py", line 497, in dispatch
    response = self.handle_exception(exc)

  File "C:\Users\项波\Desktop\flower-service\venv\lib\site-packages\rest_framework\views.py", line 457, in handle_exception
    self.raise_uncaught_exception(exc)

  File "C:\Users\项波\Desktop\flower-service\venv\lib\site-packages\rest_framework\views.py", line 468, in raise_uncaught_exception
    raise exc

  File "C:\Users\项波\Desktop\flower-service\venv\lib\site-packages\rest_framework\views.py", line 494, in dispatch
    response = handler(request, *args, **kwargs)

  File "C:\Users\项波\Desktop\flower-service\src\apps\common\decorator.py", line 17, in _func
    resp = func(*args, **kwargs)

  File "C:\Users\项波\Desktop\flower-service\src\apps\account\apis.py", line 56, in post
    user.update(user_regip=user_ip)

AttributeError: 'MyUser' object has no attribute 'update'

}}}

{{{
<WSGIRequest: POST '/api/account/login/'>
}}}
Traceback (most recent call last):
  File "C:\Users\项波\Desktop\flower-service\venv\lib\site-packages\django\core\handlers\base.py", line 113, in _get_response
    response = wrapped_callback(request, *callback_args, **callback_kwargs)
  File "C:\Users\项波\Desktop\flower-service\venv\lib\site-packages\django\views\decorators\csrf.py", line 54, in wrapped_view
    return view_func(*args, **kwargs)
  File "C:\Users\项波\Desktop\flower-service\venv\lib\site-packages\django\views\generic\base.py", line 71, in view
    return self.dispatch(request, *args, **kwargs)
  File "C:\Users\项波\Desktop\flower-service\venv\lib\site-packages\rest_framework\views.py", line 497, in dispatch
    response = self.handle_exception(exc)
  File "C:\Users\项波\Desktop\flower-service\venv\lib\site-packages\rest_framework\views.py", line 457, in handle_exception
    self.raise_uncaught_exception(exc)
  File "C:\Users\项波\Desktop\flower-service\venv\lib\site-packages\rest_framework\views.py", line 468, in raise_uncaught_exception
    raise exc
  File "C:\Users\项波\Desktop\flower-service\venv\lib\site-packages\rest_framework\views.py", line 494, in dispatch
    response = handler(request, *args, **kwargs)
  File "C:\Users\项波\Desktop\flower-service\src\apps\common\decorator.py", line 17, in _func
    resp = func(*args, **kwargs)
  File "C:\Users\项波\Desktop\flower-service\src\apps\account\apis.py", line 56, in post
    user.update(user_regip=user_ip)
AttributeError: 'MyUser' object has no attribute 'update'
2019-09-01 16:54:31,651 [Thread-6:1480] [service_mart.common.decorator:52] [ERROR]- error:error response:'MyUser' object has no attribute 'update'
2019-09-01 16:54:31,652 [Thread-6:1480] [service_mart.helper.middleware:163] [ERROR]- {{{
Traceback (most recent call last):

  File "C:\Users\项波\Desktop\flower-service\venv\lib\site-packages\django\core\handlers\base.py", line 113, in _get_response
    response = wrapped_callback(request, *callback_args, **callback_kwargs)

  File "C:\Users\项波\Desktop\flower-service\venv\lib\site-packages\django\views\decorators\csrf.py", line 54, in wrapped_view
    return view_func(*args, **kwargs)

  File "C:\Users\项波\Desktop\flower-service\venv\lib\site-packages\django\views\generic\base.py", line 71, in view
    return self.dispatch(request, *args, **kwargs)

  File "C:\Users\项波\Desktop\flower-service\venv\lib\site-packages\rest_framework\views.py", line 497, in dispatch
    response = self.handle_exception(exc)

  File "C:\Users\项波\Desktop\flower-service\venv\lib\site-packages\rest_framework\views.py", line 457, in handle_exception
    self.raise_uncaught_exception(exc)

  File "C:\Users\项波\Desktop\flower-service\venv\lib\site-packages\rest_framework\views.py", line 468, in raise_uncaught_exception
    raise exc

  File "C:\Users\项波\Desktop\flower-service\venv\lib\site-packages\rest_framework\views.py", line 494, in dispatch
    response = handler(request, *args, **kwargs)

  File "C:\Users\项波\Desktop\flower-service\src\apps\common\decorator.py", line 17, in _func
    resp = func(*args, **kwargs)

  File "C:\Users\项波\Desktop\flower-service\src\apps\account\apis.py", line 57, in post
    user.update(user_regip=user_ip)

AttributeError: 'MyUser' object has no attribute 'update'

}}}

{{{
<WSGIRequest: POST '/api/account/login/'>
}}}
Traceback (most recent call last):
  File "C:\Users\项波\Desktop\flower-service\venv\lib\site-packages\django\core\handlers\base.py", line 113, in _get_response
    response = wrapped_callback(request, *callback_args, **callback_kwargs)
  File "C:\Users\项波\Desktop\flower-service\venv\lib\site-packages\django\views\decorators\csrf.py", line 54, in wrapped_view
    return view_func(*args, **kwargs)
  File "C:\Users\项波\Desktop\flower-service\venv\lib\site-packages\django\views\generic\base.py", line 71, in view
    return self.dispatch(request, *args, **kwargs)
  File "C:\Users\项波\Desktop\flower-service\venv\lib\site-packages\rest_framework\views.py", line 497, in dispatch
    response = self.handle_exception(exc)
  File "C:\Users\项波\Desktop\flower-service\venv\lib\site-packages\rest_framework\views.py", line 457, in handle_exception
    self.raise_uncaught_exception(exc)
  File "C:\Users\项波\Desktop\flower-service\venv\lib\site-packages\rest_framework\views.py", line 468, in raise_uncaught_exception
    raise exc
  File "C:\Users\项波\Desktop\flower-service\venv\lib\site-packages\rest_framework\views.py", line 494, in dispatch
    response = handler(request, *args, **kwargs)
  File "C:\Users\项波\Desktop\flower-service\src\apps\common\decorator.py", line 17, in _func
    resp = func(*args, **kwargs)
  File "C:\Users\项波\Desktop\flower-service\src\apps\account\apis.py", line 57, in post
    user.update(user_regip=user_ip)
AttributeError: 'MyUser' object has no attribute 'update'
2019-09-01 16:55:41,427 [Thread-1:13736] [service_mart.common.decorator:52] [ERROR]- error:error response:Manager isn't accessible via MyUser instances
2019-09-01 16:55:41,430 [Thread-1:13736] [service_mart.helper.middleware:163] [ERROR]- {{{
Traceback (most recent call last):

  File "C:\Users\项波\Desktop\flower-service\venv\lib\site-packages\django\core\handlers\base.py", line 113, in _get_response
    response = wrapped_callback(request, *callback_args, **callback_kwargs)

  File "C:\Users\项波\Desktop\flower-service\venv\lib\site-packages\django\views\decorators\csrf.py", line 54, in wrapped_view
    return view_func(*args, **kwargs)

  File "C:\Users\项波\Desktop\flower-service\venv\lib\site-packages\django\views\generic\base.py", line 71, in view
    return self.dispatch(request, *args, **kwargs)

  File "C:\Users\项波\Desktop\flower-service\venv\lib\site-packages\rest_framework\views.py", line 497, in dispatch
    response = self.handle_exception(exc)

  File "C:\Users\项波\Desktop\flower-service\venv\lib\site-packages\rest_framework\views.py", line 457, in handle_exception
    self.raise_uncaught_exception(exc)

  File "C:\Users\项波\Desktop\flower-service\venv\lib\site-packages\rest_framework\views.py", line 468, in raise_uncaught_exception
    raise exc

  File "C:\Users\项波\Desktop\flower-service\venv\lib\site-packages\rest_framework\views.py", line 494, in dispatch
    response = handler(request, *args, **kwargs)

  File "C:\Users\项波\Desktop\flower-service\src\apps\common\decorator.py", line 17, in _func
    resp = func(*args, **kwargs)

  File "C:\Users\项波\Desktop\flower-service\src\apps\account\apis.py", line 54, in post
    user.objects.update(user_regip=user_ip)

  File "C:\Users\项波\Desktop\flower-service\venv\lib\site-packages\django\db\models\manager.py", line 176, in __get__
    raise AttributeError("Manager isn't accessible via %s instances" % cls.__name__)

AttributeError: Manager isn't accessible via MyUser instances

}}}

{{{
<WSGIRequest: POST '/api/account/login/'>
}}}
Traceback (most recent call last):
  File "C:\Users\项波\Desktop\flower-service\venv\lib\site-packages\django\core\handlers\base.py", line 113, in _get_response
    response = wrapped_callback(request, *callback_args, **callback_kwargs)
  File "C:\Users\项波\Desktop\flower-service\venv\lib\site-packages\django\views\decorators\csrf.py", line 54, in wrapped_view
    return view_func(*args, **kwargs)
  File "C:\Users\项波\Desktop\flower-service\venv\lib\site-packages\django\views\generic\base.py", line 71, in view
    return self.dispatch(request, *args, **kwargs)
  File "C:\Users\项波\Desktop\flower-service\venv\lib\site-packages\rest_framework\views.py", line 497, in dispatch
    response = self.handle_exception(exc)
  File "C:\Users\项波\Desktop\flower-service\venv\lib\site-packages\rest_framework\views.py", line 457, in handle_exception
    self.raise_uncaught_exception(exc)
  File "C:\Users\项波\Desktop\flower-service\venv\lib\site-packages\rest_framework\views.py", line 468, in raise_uncaught_exception
    raise exc
  File "C:\Users\项波\Desktop\flower-service\venv\lib\site-packages\rest_framework\views.py", line 494, in dispatch
    response = handler(request, *args, **kwargs)
  File "C:\Users\项波\Desktop\flower-service\src\apps\common\decorator.py", line 17, in _func
    resp = func(*args, **kwargs)
  File "C:\Users\项波\Desktop\flower-service\src\apps\account\apis.py", line 54, in post
    user.objects.update(user_regip=user_ip)
  File "C:\Users\项波\Desktop\flower-service\venv\lib\site-packages\django\db\models\manager.py", line 176, in __get__
    raise AttributeError("Manager isn't accessible via %s instances" % cls.__name__)
AttributeError: Manager isn't accessible via MyUser instances
2019-09-01 18:18:23,259 [Thread-1:12392] [service_mart.common.decorator:52] [ERROR]- error:error response:(1062, "Duplicate entry 'oV4sn4198XxyV91iEuSL5NJBg0p4' for key 'openid'")
2019-09-01 18:18:23,272 [Thread-1:12392] [service_mart.helper.middleware:163] [ERROR]- {{{
Traceback (most recent call last):

  File "C:\Users\项波\Desktop\flower-service\venv\lib\site-packages\django\db\models\query.py", line 538, in get_or_create
    return self.get(**kwargs), False

  File "C:\Users\项波\Desktop\flower-service\venv\lib\site-packages\django\db\models\query.py", line 408, in get
    self.model._meta.object_name

account.models.MyUser.DoesNotExist: MyUser matching query does not exist.


During handling of the above exception, another exception occurred:


Traceback (most recent call last):

  File "C:\Users\项波\Desktop\flower-service\venv\lib\site-packages\django\db\backends\utils.py", line 84, in _execute
    return self.cursor.execute(sql, params)

  File "C:\Users\项波\Desktop\flower-service\venv\lib\site-packages\django\db\backends\mysql\base.py", line 71, in execute
    return self.cursor.execute(query, args)

  File "C:\Users\项波\Desktop\flower-service\venv\lib\site-packages\pymysql\cursors.py", line 170, in execute
    result = self._query(query)

  File "C:\Users\项波\Desktop\flower-service\venv\lib\site-packages\pymysql\cursors.py", line 328, in _query
    conn.query(q)

  File "C:\Users\项波\Desktop\flower-service\venv\lib\site-packages\pymysql\connections.py", line 517, in query
    self._affected_rows = self._read_query_result(unbuffered=unbuffered)

  File "C:\Users\项波\Desktop\flower-service\venv\lib\site-packages\pymysql\connections.py", line 732, in _read_query_result
    result.read()

  File "C:\Users\项波\Desktop\flower-service\venv\lib\site-packages\pymysql\connections.py", line 1075, in read
    first_packet = self.connection._read_packet()

  File "C:\Users\项波\Desktop\flower-service\venv\lib\site-packages\pymysql\connections.py", line 684, in _read_packet
    packet.check_error()

  File "C:\Users\项波\Desktop\flower-service\venv\lib\site-packages\pymysql\protocol.py", line 220, in check_error
    err.raise_mysql_exception(self._data)

  File "C:\Users\项波\Desktop\flower-service\venv\lib\site-packages\pymysql\err.py", line 109, in raise_mysql_exception
    raise errorclass(errno, errval)

pymysql.err.IntegrityError: (1062, "Duplicate entry 'oV4sn4198XxyV91iEuSL5NJBg0p4' for key 'openid'")


The above exception was the direct cause of the following exception:


Traceback (most recent call last):

  File "C:\Users\项波\Desktop\flower-service\venv\lib\site-packages\django\core\handlers\base.py", line 113, in _get_response
    response = wrapped_callback(request, *callback_args, **callback_kwargs)

  File "C:\Users\项波\Desktop\flower-service\venv\lib\site-packages\django\views\decorators\csrf.py", line 54, in wrapped_view
    return view_func(*args, **kwargs)

  File "C:\Users\项波\Desktop\flower-service\venv\lib\site-packages\django\views\generic\base.py", line 71, in view
    return self.dispatch(request, *args, **kwargs)

  File "C:\Users\项波\Desktop\flower-service\venv\lib\site-packages\rest_framework\views.py", line 497, in dispatch
    response = self.handle_exception(exc)

  File "C:\Users\项波\Desktop\flower-service\venv\lib\site-packages\rest_framework\views.py", line 457, in handle_exception
    self.raise_uncaught_exception(exc)

  File "C:\Users\项波\Desktop\flower-service\venv\lib\site-packages\rest_framework\views.py", line 468, in raise_uncaught_exception
    raise exc

  File "C:\Users\项波\Desktop\flower-service\venv\lib\site-packages\rest_framework\views.py", line 494, in dispatch
    response = handler(request, *args, **kwargs)

  File "C:\Users\项波\Desktop\flower-service\src\apps\common\decorator.py", line 17, in _func
    resp = func(*args, **kwargs)

  File "C:\Users\项波\Desktop\flower-service\src\apps\account\apis.py", line 53, in post
    user_lastip=user_ip,

  File "C:\Users\项波\Desktop\flower-service\venv\lib\site-packages\django\db\models\manager.py", line 82, in manager_method
    return getattr(self.get_queryset(), name)(*args, **kwargs)

  File "C:\Users\项波\Desktop\flower-service\venv\lib\site-packages\django\db\models\query.py", line 541, in get_or_create
    return self._create_object_from_params(kwargs, params)

  File "C:\Users\项波\Desktop\flower-service\venv\lib\site-packages\django\db\models\query.py", line 583, in _create_object_from_params
    raise e

  File "C:\Users\项波\Desktop\flower-service\venv\lib\site-packages\django\db\models\query.py", line 575, in _create_object_from_params
    obj = self.create(**params)

  File "C:\Users\项波\Desktop\flower-service\venv\lib\site-packages\django\db\models\query.py", line 422, in create
    obj.save(force_insert=True, using=self.db)

  File "C:\Users\项波\Desktop\flower-service\venv\lib\site-packages\django\contrib\auth\base_user.py", line 66, in save
    super().save(*args, **kwargs)

  File "C:\Users\项波\Desktop\flower-service\venv\lib\site-packages\django\db\models\base.py", line 741, in save
    force_update=force_update, update_fields=update_fields)

  File "C:\Users\项波\Desktop\flower-service\venv\lib\site-packages\django\db\models\base.py", line 779, in save_base
    force_update, using, update_fields,

  File "C:\Users\项波\Desktop\flower-service\venv\lib\site-packages\django\db\models\base.py", line 870, in _save_table
    result = self._do_insert(cls._base_manager, using, fields, update_pk, raw)

  File "C:\Users\项波\Desktop\flower-service\venv\lib\site-packages\django\db\models\base.py", line 908, in _do_insert
    using=using, raw=raw)

  File "C:\Users\项波\Desktop\flower-service\venv\lib\site-packages\django\db\models\manager.py", line 82, in manager_method
    return getattr(self.get_queryset(), name)(*args, **kwargs)

  File "C:\Users\项波\Desktop\flower-service\venv\lib\site-packages\django\db\models\query.py", line 1186, in _insert
    return query.get_compiler(using=using).execute_sql(return_id)

  File "C:\Users\项波\Desktop\flower-service\venv\lib\site-packages\django\db\models\sql\compiler.py", line 1335, in execute_sql
    cursor.execute(sql, params)

  File "C:\Users\项波\Desktop\flower-service\venv\lib\site-packages\django\db\backends\utils.py", line 99, in execute
    return super().execute(sql, params)

  File "C:\Users\项波\Desktop\flower-service\venv\lib\site-packages\django\db\backends\utils.py", line 67, in execute
    return self._execute_with_wrappers(sql, params, many=False, executor=self._execute)

  File "C:\Users\项波\Desktop\flower-service\venv\lib\site-packages\django\db\backends\utils.py", line 76, in _execute_with_wrappers
    return executor(sql, params, many, context)

  File "C:\Users\项波\Desktop\flower-service\venv\lib\site-packages\django\db\backends\utils.py", line 84, in _execute
    return self.cursor.execute(sql, params)

  File "C:\Users\项波\Desktop\flower-service\venv\lib\site-packages\django\db\utils.py", line 89, in __exit__
    raise dj_exc_value.with_traceback(traceback) from exc_value

  File "C:\Users\项波\Desktop\flower-service\venv\lib\site-packages\django\db\backends\utils.py", line 84, in _execute
    return self.cursor.execute(sql, params)

  File "C:\Users\项波\Desktop\flower-service\venv\lib\site-packages\django\db\backends\mysql\base.py", line 71, in execute
    return self.cursor.execute(query, args)

  File "C:\Users\项波\Desktop\flower-service\venv\lib\site-packages\pymysql\cursors.py", line 170, in execute
    result = self._query(query)

  File "C:\Users\项波\Desktop\flower-service\venv\lib\site-packages\pymysql\cursors.py", line 328, in _query
    conn.query(q)

  File "C:\Users\项波\Desktop\flower-service\venv\lib\site-packages\pymysql\connections.py", line 517, in query
    self._affected_rows = self._read_query_result(unbuffered=unbuffered)

  File "C:\Users\项波\Desktop\flower-service\venv\lib\site-packages\pymysql\connections.py", line 732, in _read_query_result
    result.read()

  File "C:\Users\项波\Desktop\flower-service\venv\lib\site-packages\pymysql\connections.py", line 1075, in read
    first_packet = self.connection._read_packet()

  File "C:\Users\项波\Desktop\flower-service\venv\lib\site-packages\pymysql\connections.py", line 684, in _read_packet
    packet.check_error()

  File "C:\Users\项波\Desktop\flower-service\venv\lib\site-packages\pymysql\protocol.py", line 220, in check_error
    err.raise_mysql_exception(self._data)

  File "C:\Users\项波\Desktop\flower-service\venv\lib\site-packages\pymysql\err.py", line 109, in raise_mysql_exception
    raise errorclass(errno, errval)

django.db.utils.IntegrityError: (1062, "Duplicate entry 'oV4sn4198XxyV91iEuSL5NJBg0p4' for key 'openid'")

}}}

{{{
<WSGIRequest: POST '/api/account/login/'>
}}}
Traceback (most recent call last):
  File "C:\Users\项波\Desktop\flower-service\venv\lib\site-packages\django\db\models\query.py", line 538, in get_or_create
    return self.get(**kwargs), False
  File "C:\Users\项波\Desktop\flower-service\venv\lib\site-packages\django\db\models\query.py", line 408, in get
    self.model._meta.object_name
account.models.MyUser.DoesNotExist: MyUser matching query does not exist.

During handling of the above exception, another exception occurred:

Traceback (most recent call last):
  File "C:\Users\项波\Desktop\flower-service\venv\lib\site-packages\django\db\backends\utils.py", line 84, in _execute
    return self.cursor.execute(sql, params)
  File "C:\Users\项波\Desktop\flower-service\venv\lib\site-packages\django\db\backends\mysql\base.py", line 71, in execute
    return self.cursor.execute(query, args)
  File "C:\Users\项波\Desktop\flower-service\venv\lib\site-packages\pymysql\cursors.py", line 170, in execute
    result = self._query(query)
  File "C:\Users\项波\Desktop\flower-service\venv\lib\site-packages\pymysql\cursors.py", line 328, in _query
    conn.query(q)
  File "C:\Users\项波\Desktop\flower-service\venv\lib\site-packages\pymysql\connections.py", line 517, in query
    self._affected_rows = self._read_query_result(unbuffered=unbuffered)
  File "C:\Users\项波\Desktop\flower-service\venv\lib\site-packages\pymysql\connections.py", line 732, in _read_query_result
    result.read()
  File "C:\Users\项波\Desktop\flower-service\venv\lib\site-packages\pymysql\connections.py", line 1075, in read
    first_packet = self.connection._read_packet()
  File "C:\Users\项波\Desktop\flower-service\venv\lib\site-packages\pymysql\connections.py", line 684, in _read_packet
    packet.check_error()
  File "C:\Users\项波\Desktop\flower-service\venv\lib\site-packages\pymysql\protocol.py", line 220, in check_error
    err.raise_mysql_exception(self._data)
  File "C:\Users\项波\Desktop\flower-service\venv\lib\site-packages\pymysql\err.py", line 109, in raise_mysql_exception
    raise errorclass(errno, errval)
pymysql.err.IntegrityError: (1062, "Duplicate entry 'oV4sn4198XxyV91iEuSL5NJBg0p4' for key 'openid'")

The above exception was the direct cause of the following exception:

Traceback (most recent call last):
  File "C:\Users\项波\Desktop\flower-service\venv\lib\site-packages\django\core\handlers\base.py", line 113, in _get_response
    response = wrapped_callback(request, *callback_args, **callback_kwargs)
  File "C:\Users\项波\Desktop\flower-service\venv\lib\site-packages\django\views\decorators\csrf.py", line 54, in wrapped_view
    return view_func(*args, **kwargs)
  File "C:\Users\项波\Desktop\flower-service\venv\lib\site-packages\django\views\generic\base.py", line 71, in view
    return self.dispatch(request, *args, **kwargs)
  File "C:\Users\项波\Desktop\flower-service\venv\lib\site-packages\rest_framework\views.py", line 497, in dispatch
    response = self.handle_exception(exc)
  File "C:\Users\项波\Desktop\flower-service\venv\lib\site-packages\rest_framework\views.py", line 457, in handle_exception
    self.raise_uncaught_exception(exc)
  File "C:\Users\项波\Desktop\flower-service\venv\lib\site-packages\rest_framework\views.py", line 468, in raise_uncaught_exception
    raise exc
  File "C:\Users\项波\Desktop\flower-service\venv\lib\site-packages\rest_framework\views.py", line 494, in dispatch
    response = handler(request, *args, **kwargs)
  File "C:\Users\项波\Desktop\flower-service\src\apps\common\decorator.py", line 17, in _func
    resp = func(*args, **kwargs)
  File "C:\Users\项波\Desktop\flower-service\src\apps\account\apis.py", line 53, in post
    user_lastip=user_ip,
  File "C:\Users\项波\Desktop\flower-service\venv\lib\site-packages\django\db\models\manager.py", line 82, in manager_method
    return getattr(self.get_queryset(), name)(*args, **kwargs)
  File "C:\Users\项波\Desktop\flower-service\venv\lib\site-packages\django\db\models\query.py", line 541, in get_or_create
    return self._create_object_from_params(kwargs, params)
  File "C:\Users\项波\Desktop\flower-service\venv\lib\site-packages\django\db\models\query.py", line 583, in _create_object_from_params
    raise e
  File "C:\Users\项波\Desktop\flower-service\venv\lib\site-packages\django\db\models\query.py", line 575, in _create_object_from_params
    obj = self.create(**params)
  File "C:\Users\项波\Desktop\flower-service\venv\lib\site-packages\django\db\models\query.py", line 422, in create
    obj.save(force_insert=True, using=self.db)
  File "C:\Users\项波\Desktop\flower-service\venv\lib\site-packages\django\contrib\auth\base_user.py", line 66, in save
    super().save(*args, **kwargs)
  File "C:\Users\项波\Desktop\flower-service\venv\lib\site-packages\django\db\models\base.py", line 741, in save
    force_update=force_update, update_fields=update_fields)
  File "C:\Users\项波\Desktop\flower-service\venv\lib\site-packages\django\db\models\base.py", line 779, in save_base
    force_update, using, update_fields,
  File "C:\Users\项波\Desktop\flower-service\venv\lib\site-packages\django\db\models\base.py", line 870, in _save_table
    result = self._do_insert(cls._base_manager, using, fields, update_pk, raw)
  File "C:\Users\项波\Desktop\flower-service\venv\lib\site-packages\django\db\models\base.py", line 908, in _do_insert
    using=using, raw=raw)
  File "C:\Users\项波\Desktop\flower-service\venv\lib\site-packages\django\db\models\manager.py", line 82, in manager_method
    return getattr(self.get_queryset(), name)(*args, **kwargs)
  File "C:\Users\项波\Desktop\flower-service\venv\lib\site-packages\django\db\models\query.py", line 1186, in _insert
    return query.get_compiler(using=using).execute_sql(return_id)
  File "C:\Users\项波\Desktop\flower-service\venv\lib\site-packages\django\db\models\sql\compiler.py", line 1335, in execute_sql
    cursor.execute(sql, params)
  File "C:\Users\项波\Desktop\flower-service\venv\lib\site-packages\django\db\backends\utils.py", line 99, in execute
    return super().execute(sql, params)
  File "C:\Users\项波\Desktop\flower-service\venv\lib\site-packages\django\db\backends\utils.py", line 67, in execute
    return self._execute_with_wrappers(sql, params, many=False, executor=self._execute)
  File "C:\Users\项波\Desktop\flower-service\venv\lib\site-packages\django\db\backends\utils.py", line 76, in _execute_with_wrappers
    return executor(sql, params, many, context)
  File "C:\Users\项波\Desktop\flower-service\venv\lib\site-packages\django\db\backends\utils.py", line 84, in _execute
    return self.cursor.execute(sql, params)
  File "C:\Users\项波\Desktop\flower-service\venv\lib\site-packages\django\db\utils.py", line 89, in __exit__
    raise dj_exc_value.with_traceback(traceback) from exc_value
  File "C:\Users\项波\Desktop\flower-service\venv\lib\site-packages\django\db\backends\utils.py", line 84, in _execute
    return self.cursor.execute(sql, params)
  File "C:\Users\项波\Desktop\flower-service\venv\lib\site-packages\django\db\backends\mysql\base.py", line 71, in execute
    return self.cursor.execute(query, args)
  File "C:\Users\项波\Desktop\flower-service\venv\lib\site-packages\pymysql\cursors.py", line 170, in execute
    result = self._query(query)
  File "C:\Users\项波\Desktop\flower-service\venv\lib\site-packages\pymysql\cursors.py", line 328, in _query
    conn.query(q)
  File "C:\Users\项波\Desktop\flower-service\venv\lib\site-packages\pymysql\connections.py", line 517, in query
    self._affected_rows = self._read_query_result(unbuffered=unbuffered)
  File "C:\Users\项波\Desktop\flower-service\venv\lib\site-packages\pymysql\connections.py", line 732, in _read_query_result
    result.read()
  File "C:\Users\项波\Desktop\flower-service\venv\lib\site-packages\pymysql\connections.py", line 1075, in read
    first_packet = self.connection._read_packet()
  File "C:\Users\项波\Desktop\flower-service\venv\lib\site-packages\pymysql\connections.py", line 684, in _read_packet
    packet.check_error()
  File "C:\Users\项波\Desktop\flower-service\venv\lib\site-packages\pymysql\protocol.py", line 220, in check_error
    err.raise_mysql_exception(self._data)
  File "C:\Users\项波\Desktop\flower-service\venv\lib\site-packages\pymysql\err.py", line 109, in raise_mysql_exception
    raise errorclass(errno, errval)
django.db.utils.IntegrityError: (1062, "Duplicate entry 'oV4sn4198XxyV91iEuSL5NJBg0p4' for key 'openid'")
2019-09-01 18:20:04,455 [Thread-1:10652] [service_mart.common.decorator:52] [ERROR]- error:error response:(1062, "Duplicate entry 'oV4sn4198XxyV91iEuSL5NJBg0p4' for key 'openid'")
2019-09-01 18:20:04,461 [Thread-1:10652] [service_mart.helper.middleware:163] [ERROR]- {{{
Traceback (most recent call last):

  File "C:\Users\项波\Desktop\flower-service\venv\lib\site-packages\django\db\models\query.py", line 538, in get_or_create
    return self.get(**kwargs), False

  File "C:\Users\项波\Desktop\flower-service\venv\lib\site-packages\django\db\models\query.py", line 408, in get
    self.model._meta.object_name

account.models.MyUser.DoesNotExist: MyUser matching query does not exist.


During handling of the above exception, another exception occurred:


Traceback (most recent call last):

  File "C:\Users\项波\Desktop\flower-service\venv\lib\site-packages\django\db\backends\utils.py", line 84, in _execute
    return self.cursor.execute(sql, params)

  File "C:\Users\项波\Desktop\flower-service\venv\lib\site-packages\django\db\backends\mysql\base.py", line 71, in execute
    return self.cursor.execute(query, args)

  File "C:\Users\项波\Desktop\flower-service\venv\lib\site-packages\pymysql\cursors.py", line 170, in execute
    result = self._query(query)

  File "C:\Users\项波\Desktop\flower-service\venv\lib\site-packages\pymysql\cursors.py", line 328, in _query
    conn.query(q)

  File "C:\Users\项波\Desktop\flower-service\venv\lib\site-packages\pymysql\connections.py", line 517, in query
    self._affected_rows = self._read_query_result(unbuffered=unbuffered)

  File "C:\Users\项波\Desktop\flower-service\venv\lib\site-packages\pymysql\connections.py", line 732, in _read_query_result
    result.read()

  File "C:\Users\项波\Desktop\flower-service\venv\lib\site-packages\pymysql\connections.py", line 1075, in read
    first_packet = self.connection._read_packet()

  File "C:\Users\项波\Desktop\flower-service\venv\lib\site-packages\pymysql\connections.py", line 684, in _read_packet
    packet.check_error()

  File "C:\Users\项波\Desktop\flower-service\venv\lib\site-packages\pymysql\protocol.py", line 220, in check_error
    err.raise_mysql_exception(self._data)

  File "C:\Users\项波\Desktop\flower-service\venv\lib\site-packages\pymysql\err.py", line 109, in raise_mysql_exception
    raise errorclass(errno, errval)

pymysql.err.IntegrityError: (1062, "Duplicate entry 'oV4sn4198XxyV91iEuSL5NJBg0p4' for key 'openid'")


The above exception was the direct cause of the following exception:


Traceback (most recent call last):

  File "C:\Users\项波\Desktop\flower-service\venv\lib\site-packages\django\core\handlers\base.py", line 113, in _get_response
    response = wrapped_callback(request, *callback_args, **callback_kwargs)

  File "C:\Users\项波\Desktop\flower-service\venv\lib\site-packages\django\views\decorators\csrf.py", line 54, in wrapped_view
    return view_func(*args, **kwargs)

  File "C:\Users\项波\Desktop\flower-service\venv\lib\site-packages\django\views\generic\base.py", line 71, in view
    return self.dispatch(request, *args, **kwargs)

  File "C:\Users\项波\Desktop\flower-service\venv\lib\site-packages\rest_framework\views.py", line 497, in dispatch
    response = self.handle_exception(exc)

  File "C:\Users\项波\Desktop\flower-service\venv\lib\site-packages\rest_framework\views.py", line 457, in handle_exception
    self.raise_uncaught_exception(exc)

  File "C:\Users\项波\Desktop\flower-service\venv\lib\site-packages\rest_framework\views.py", line 468, in raise_uncaught_exception
    raise exc

  File "C:\Users\项波\Desktop\flower-service\venv\lib\site-packages\rest_framework\views.py", line 494, in dispatch
    response = handler(request, *args, **kwargs)

  File "C:\Users\项波\Desktop\flower-service\src\apps\common\decorator.py", line 17, in _func
    resp = func(*args, **kwargs)

  File "C:\Users\项波\Desktop\flower-service\src\apps\account\apis.py", line 53, in post
    password=openid,

  File "C:\Users\项波\Desktop\flower-service\venv\lib\site-packages\django\db\models\manager.py", line 82, in manager_method
    return getattr(self.get_queryset(), name)(*args, **kwargs)

  File "C:\Users\项波\Desktop\flower-service\venv\lib\site-packages\django\db\models\query.py", line 541, in get_or_create
    return self._create_object_from_params(kwargs, params)

  File "C:\Users\项波\Desktop\flower-service\venv\lib\site-packages\django\db\models\query.py", line 583, in _create_object_from_params
    raise e

  File "C:\Users\项波\Desktop\flower-service\venv\lib\site-packages\django\db\models\query.py", line 575, in _create_object_from_params
    obj = self.create(**params)

  File "C:\Users\项波\Desktop\flower-service\venv\lib\site-packages\django\db\models\query.py", line 422, in create
    obj.save(force_insert=True, using=self.db)

  File "C:\Users\项波\Desktop\flower-service\venv\lib\site-packages\django\contrib\auth\base_user.py", line 66, in save
    super().save(*args, **kwargs)

  File "C:\Users\项波\Desktop\flower-service\venv\lib\site-packages\django\db\models\base.py", line 741, in save
    force_update=force_update, update_fields=update_fields)

  File "C:\Users\项波\Desktop\flower-service\venv\lib\site-packages\django\db\models\base.py", line 779, in save_base
    force_update, using, update_fields,

  File "C:\Users\项波\Desktop\flower-service\venv\lib\site-packages\django\db\models\base.py", line 870, in _save_table
    result = self._do_insert(cls._base_manager, using, fields, update_pk, raw)

  File "C:\Users\项波\Desktop\flower-service\venv\lib\site-packages\django\db\models\base.py", line 908, in _do_insert
    using=using, raw=raw)

  File "C:\Users\项波\Desktop\flower-service\venv\lib\site-packages\django\db\models\manager.py", line 82, in manager_method
    return getattr(self.get_queryset(), name)(*args, **kwargs)

  File "C:\Users\项波\Desktop\flower-service\venv\lib\site-packages\django\db\models\query.py", line 1186, in _insert
    return query.get_compiler(using=using).execute_sql(return_id)

  File "C:\Users\项波\Desktop\flower-service\venv\lib\site-packages\django\db\models\sql\compiler.py", line 1335, in execute_sql
    cursor.execute(sql, params)

  File "C:\Users\项波\Desktop\flower-service\venv\lib\site-packages\django\db\backends\utils.py", line 99, in execute
    return super().execute(sql, params)

  File "C:\Users\项波\Desktop\flower-service\venv\lib\site-packages\django\db\backends\utils.py", line 67, in execute
    return self._execute_with_wrappers(sql, params, many=False, executor=self._execute)

  File "C:\Users\项波\Desktop\flower-service\venv\lib\site-packages\django\db\backends\utils.py", line 76, in _execute_with_wrappers
    return executor(sql, params, many, context)

  File "C:\Users\项波\Desktop\flower-service\venv\lib\site-packages\django\db\backends\utils.py", line 84, in _execute
    return self.cursor.execute(sql, params)

  File "C:\Users\项波\Desktop\flower-service\venv\lib\site-packages\django\db\utils.py", line 89, in __exit__
    raise dj_exc_value.with_traceback(traceback) from exc_value

  File "C:\Users\项波\Desktop\flower-service\venv\lib\site-packages\django\db\backends\utils.py", line 84, in _execute
    return self.cursor.execute(sql, params)

  File "C:\Users\项波\Desktop\flower-service\venv\lib\site-packages\django\db\backends\mysql\base.py", line 71, in execute
    return self.cursor.execute(query, args)

  File "C:\Users\项波\Desktop\flower-service\venv\lib\site-packages\pymysql\cursors.py", line 170, in execute
    result = self._query(query)

  File "C:\Users\项波\Desktop\flower-service\venv\lib\site-packages\pymysql\cursors.py", line 328, in _query
    conn.query(q)

  File "C:\Users\项波\Desktop\flower-service\venv\lib\site-packages\pymysql\connections.py", line 517, in query
    self._affected_rows = self._read_query_result(unbuffered=unbuffered)

  File "C:\Users\项波\Desktop\flower-service\venv\lib\site-packages\pymysql\connections.py", line 732, in _read_query_result
    result.read()

  File "C:\Users\项波\Desktop\flower-service\venv\lib\site-packages\pymysql\connections.py", line 1075, in read
    first_packet = self.connection._read_packet()

  File "C:\Users\项波\Desktop\flower-service\venv\lib\site-packages\pymysql\connections.py", line 684, in _read_packet
    packet.check_error()

  File "C:\Users\项波\Desktop\flower-service\venv\lib\site-packages\pymysql\protocol.py", line 220, in check_error
    err.raise_mysql_exception(self._data)

  File "C:\Users\项波\Desktop\flower-service\venv\lib\site-packages\pymysql\err.py", line 109, in raise_mysql_exception
    raise errorclass(errno, errval)

django.db.utils.IntegrityError: (1062, "Duplicate entry 'oV4sn4198XxyV91iEuSL5NJBg0p4' for key 'openid'")

}}}

{{{
<WSGIRequest: POST '/api/account/login/'>
}}}
Traceback (most recent call last):
  File "C:\Users\项波\Desktop\flower-service\venv\lib\site-packages\django\db\models\query.py", line 538, in get_or_create
    return self.get(**kwargs), False
  File "C:\Users\项波\Desktop\flower-service\venv\lib\site-packages\django\db\models\query.py", line 408, in get
    self.model._meta.object_name
account.models.MyUser.DoesNotExist: MyUser matching query does not exist.

During handling of the above exception, another exception occurred:

Traceback (most recent call last):
  File "C:\Users\项波\Desktop\flower-service\venv\lib\site-packages\django\db\backends\utils.py", line 84, in _execute
    return self.cursor.execute(sql, params)
  File "C:\Users\项波\Desktop\flower-service\venv\lib\site-packages\django\db\backends\mysql\base.py", line 71, in execute
    return self.cursor.execute(query, args)
  File "C:\Users\项波\Desktop\flower-service\venv\lib\site-packages\pymysql\cursors.py", line 170, in execute
    result = self._query(query)
  File "C:\Users\项波\Desktop\flower-service\venv\lib\site-packages\pymysql\cursors.py", line 328, in _query
    conn.query(q)
  File "C:\Users\项波\Desktop\flower-service\venv\lib\site-packages\pymysql\connections.py", line 517, in query
    self._affected_rows = self._read_query_result(unbuffered=unbuffered)
  File "C:\Users\项波\Desktop\flower-service\venv\lib\site-packages\pymysql\connections.py", line 732, in _read_query_result
    result.read()
  File "C:\Users\项波\Desktop\flower-service\venv\lib\site-packages\pymysql\connections.py", line 1075, in read
    first_packet = self.connection._read_packet()
  File "C:\Users\项波\Desktop\flower-service\venv\lib\site-packages\pymysql\connections.py", line 684, in _read_packet
    packet.check_error()
  File "C:\Users\项波\Desktop\flower-service\venv\lib\site-packages\pymysql\protocol.py", line 220, in check_error
    err.raise_mysql_exception(self._data)
  File "C:\Users\项波\Desktop\flower-service\venv\lib\site-packages\pymysql\err.py", line 109, in raise_mysql_exception
    raise errorclass(errno, errval)
pymysql.err.IntegrityError: (1062, "Duplicate entry 'oV4sn4198XxyV91iEuSL5NJBg0p4' for key 'openid'")

The above exception was the direct cause of the following exception:

Traceback (most recent call last):
  File "C:\Users\项波\Desktop\flower-service\venv\lib\site-packages\django\core\handlers\base.py", line 113, in _get_response
    response = wrapped_callback(request, *callback_args, **callback_kwargs)
  File "C:\Users\项波\Desktop\flower-service\venv\lib\site-packages\django\views\decorators\csrf.py", line 54, in wrapped_view
    return view_func(*args, **kwargs)
  File "C:\Users\项波\Desktop\flower-service\venv\lib\site-packages\django\views\generic\base.py", line 71, in view
    return self.dispatch(request, *args, **kwargs)
  File "C:\Users\项波\Desktop\flower-service\venv\lib\site-packages\rest_framework\views.py", line 497, in dispatch
    response = self.handle_exception(exc)
  File "C:\Users\项波\Desktop\flower-service\venv\lib\site-packages\rest_framework\views.py", line 457, in handle_exception
    self.raise_uncaught_exception(exc)
  File "C:\Users\项波\Desktop\flower-service\venv\lib\site-packages\rest_framework\views.py", line 468, in raise_uncaught_exception
    raise exc
  File "C:\Users\项波\Desktop\flower-service\venv\lib\site-packages\rest_framework\views.py", line 494, in dispatch
    response = handler(request, *args, **kwargs)
  File "C:\Users\项波\Desktop\flower-service\src\apps\common\decorator.py", line 17, in _func
    resp = func(*args, **kwargs)
  File "C:\Users\项波\Desktop\flower-service\src\apps\account\apis.py", line 53, in post
    password=openid,
  File "C:\Users\项波\Desktop\flower-service\venv\lib\site-packages\django\db\models\manager.py", line 82, in manager_method
    return getattr(self.get_queryset(), name)(*args, **kwargs)
  File "C:\Users\项波\Desktop\flower-service\venv\lib\site-packages\django\db\models\query.py", line 541, in get_or_create
    return self._create_object_from_params(kwargs, params)
  File "C:\Users\项波\Desktop\flower-service\venv\lib\site-packages\django\db\models\query.py", line 583, in _create_object_from_params
    raise e
  File "C:\Users\项波\Desktop\flower-service\venv\lib\site-packages\django\db\models\query.py", line 575, in _create_object_from_params
    obj = self.create(**params)
  File "C:\Users\项波\Desktop\flower-service\venv\lib\site-packages\django\db\models\query.py", line 422, in create
    obj.save(force_insert=True, using=self.db)
  File "C:\Users\项波\Desktop\flower-service\venv\lib\site-packages\django\contrib\auth\base_user.py", line 66, in save
    super().save(*args, **kwargs)
  File "C:\Users\项波\Desktop\flower-service\venv\lib\site-packages\django\db\models\base.py", line 741, in save
    force_update=force_update, update_fields=update_fields)
  File "C:\Users\项波\Desktop\flower-service\venv\lib\site-packages\django\db\models\base.py", line 779, in save_base
    force_update, using, update_fields,
  File "C:\Users\项波\Desktop\flower-service\venv\lib\site-packages\django\db\models\base.py", line 870, in _save_table
    result = self._do_insert(cls._base_manager, using, fields, update_pk, raw)
  File "C:\Users\项波\Desktop\flower-service\venv\lib\site-packages\django\db\models\base.py", line 908, in _do_insert
    using=using, raw=raw)
  File "C:\Users\项波\Desktop\flower-service\venv\lib\site-packages\django\db\models\manager.py", line 82, in manager_method
    return getattr(self.get_queryset(), name)(*args, **kwargs)
  File "C:\Users\项波\Desktop\flower-service\venv\lib\site-packages\django\db\models\query.py", line 1186, in _insert
    return query.get_compiler(using=using).execute_sql(return_id)
  File "C:\Users\项波\Desktop\flower-service\venv\lib\site-packages\django\db\models\sql\compiler.py", line 1335, in execute_sql
    cursor.execute(sql, params)
  File "C:\Users\项波\Desktop\flower-service\venv\lib\site-packages\django\db\backends\utils.py", line 99, in execute
    return super().execute(sql, params)
  File "C:\Users\项波\Desktop\flower-service\venv\lib\site-packages\django\db\backends\utils.py", line 67, in execute
    return self._execute_with_wrappers(sql, params, many=False, executor=self._execute)
  File "C:\Users\项波\Desktop\flower-service\venv\lib\site-packages\django\db\backends\utils.py", line 76, in _execute_with_wrappers
    return executor(sql, params, many, context)
  File "C:\Users\项波\Desktop\flower-service\venv\lib\site-packages\django\db\backends\utils.py", line 84, in _execute
    return self.cursor.execute(sql, params)
  File "C:\Users\项波\Desktop\flower-service\venv\lib\site-packages\django\db\utils.py", line 89, in __exit__
    raise dj_exc_value.with_traceback(traceback) from exc_value
  File "C:\Users\项波\Desktop\flower-service\venv\lib\site-packages\django\db\backends\utils.py", line 84, in _execute
    return self.cursor.execute(sql, params)
  File "C:\Users\项波\Desktop\flower-service\venv\lib\site-packages\django\db\backends\mysql\base.py", line 71, in execute
    return self.cursor.execute(query, args)
  File "C:\Users\项波\Desktop\flower-service\venv\lib\site-packages\pymysql\cursors.py", line 170, in execute
    result = self._query(query)
  File "C:\Users\项波\Desktop\flower-service\venv\lib\site-packages\pymysql\cursors.py", line 328, in _query
    conn.query(q)
  File "C:\Users\项波\Desktop\flower-service\venv\lib\site-packages\pymysql\connections.py", line 517, in query
    self._affected_rows = self._read_query_result(unbuffered=unbuffered)
  File "C:\Users\项波\Desktop\flower-service\venv\lib\site-packages\pymysql\connections.py", line 732, in _read_query_result
    result.read()
  File "C:\Users\项波\Desktop\flower-service\venv\lib\site-packages\pymysql\connections.py", line 1075, in read
    first_packet = self.connection._read_packet()
  File "C:\Users\项波\Desktop\flower-service\venv\lib\site-packages\pymysql\connections.py", line 684, in _read_packet
    packet.check_error()
  File "C:\Users\项波\Desktop\flower-service\venv\lib\site-packages\pymysql\protocol.py", line 220, in check_error
    err.raise_mysql_exception(self._data)
  File "C:\Users\项波\Desktop\flower-service\venv\lib\site-packages\pymysql\err.py", line 109, in raise_mysql_exception
    raise errorclass(errno, errval)
django.db.utils.IntegrityError: (1062, "Duplicate entry 'oV4sn4198XxyV91iEuSL5NJBg0p4' for key 'openid'")
2019-09-01 21:50:02,021 [Thread-6:12240] [service_mart.common.decorator:52] [ERROR]- error:error response:(1062, "Duplicate entry 'oV4sn4198XxyV91iEuSL5NJBg0p4' for key 'openid'")
2019-09-01 21:50:02,036 [Thread-6:12240] [service_mart.helper.middleware:163] [ERROR]- {{{
Traceback (most recent call last):

  File "C:\Users\项波\Desktop\flower-service\venv\lib\site-packages\django\db\models\query.py", line 538, in get_or_create
    return self.get(**kwargs), False

  File "C:\Users\项波\Desktop\flower-service\venv\lib\site-packages\django\db\models\query.py", line 408, in get
    self.model._meta.object_name

account.models.MyUser.DoesNotExist: MyUser matching query does not exist.


During handling of the above exception, another exception occurred:


Traceback (most recent call last):

  File "C:\Users\项波\Desktop\flower-service\venv\lib\site-packages\django\db\backends\utils.py", line 84, in _execute
    return self.cursor.execute(sql, params)

  File "C:\Users\项波\Desktop\flower-service\venv\lib\site-packages\django\db\backends\mysql\base.py", line 71, in execute
    return self.cursor.execute(query, args)

  File "C:\Users\项波\Desktop\flower-service\venv\lib\site-packages\pymysql\cursors.py", line 170, in execute
    result = self._query(query)

  File "C:\Users\项波\Desktop\flower-service\venv\lib\site-packages\pymysql\cursors.py", line 328, in _query
    conn.query(q)

  File "C:\Users\项波\Desktop\flower-service\venv\lib\site-packages\pymysql\connections.py", line 517, in query
    self._affected_rows = self._read_query_result(unbuffered=unbuffered)

  File "C:\Users\项波\Desktop\flower-service\venv\lib\site-packages\pymysql\connections.py", line 732, in _read_query_result
    result.read()

  File "C:\Users\项波\Desktop\flower-service\venv\lib\site-packages\pymysql\connections.py", line 1075, in read
    first_packet = self.connection._read_packet()

  File "C:\Users\项波\Desktop\flower-service\venv\lib\site-packages\pymysql\connections.py", line 684, in _read_packet
    packet.check_error()

  File "C:\Users\项波\Desktop\flower-service\venv\lib\site-packages\pymysql\protocol.py", line 220, in check_error
    err.raise_mysql_exception(self._data)

  File "C:\Users\项波\Desktop\flower-service\venv\lib\site-packages\pymysql\err.py", line 109, in raise_mysql_exception
    raise errorclass(errno, errval)

pymysql.err.IntegrityError: (1062, "Duplicate entry 'oV4sn4198XxyV91iEuSL5NJBg0p4' for key 'openid'")


The above exception was the direct cause of the following exception:


Traceback (most recent call last):

  File "C:\Users\项波\Desktop\flower-service\venv\lib\site-packages\django\core\handlers\base.py", line 113, in _get_response
    response = wrapped_callback(request, *callback_args, **callback_kwargs)

  File "C:\Users\项波\Desktop\flower-service\venv\lib\site-packages\django\views\decorators\csrf.py", line 54, in wrapped_view
    return view_func(*args, **kwargs)

  File "C:\Users\项波\Desktop\flower-service\venv\lib\site-packages\django\views\generic\base.py", line 71, in view
    return self.dispatch(request, *args, **kwargs)

  File "C:\Users\项波\Desktop\flower-service\venv\lib\site-packages\rest_framework\views.py", line 497, in dispatch
    response = self.handle_exception(exc)

  File "C:\Users\项波\Desktop\flower-service\venv\lib\site-packages\rest_framework\views.py", line 457, in handle_exception
    self.raise_uncaught_exception(exc)

  File "C:\Users\项波\Desktop\flower-service\venv\lib\site-packages\rest_framework\views.py", line 468, in raise_uncaught_exception
    raise exc

  File "C:\Users\项波\Desktop\flower-service\venv\lib\site-packages\rest_framework\views.py", line 494, in dispatch
    response = handler(request, *args, **kwargs)

  File "C:\Users\项波\Desktop\flower-service\src\apps\common\decorator.py", line 17, in _func
    resp = func(*args, **kwargs)

  File "C:\Users\项波\Desktop\flower-service\src\apps\account\apis.py", line 51, in post
    user_lastip=user_ip,

  File "C:\Users\项波\Desktop\flower-service\venv\lib\site-packages\django\db\models\manager.py", line 82, in manager_method
    return getattr(self.get_queryset(), name)(*args, **kwargs)

  File "C:\Users\项波\Desktop\flower-service\venv\lib\site-packages\django\db\models\query.py", line 541, in get_or_create
    return self._create_object_from_params(kwargs, params)

  File "C:\Users\项波\Desktop\flower-service\venv\lib\site-packages\django\db\models\query.py", line 583, in _create_object_from_params
    raise e

  File "C:\Users\项波\Desktop\flower-service\venv\lib\site-packages\django\db\models\query.py", line 575, in _create_object_from_params
    obj = self.create(**params)

  File "C:\Users\项波\Desktop\flower-service\venv\lib\site-packages\django\db\models\query.py", line 422, in create
    obj.save(force_insert=True, using=self.db)

  File "C:\Users\项波\Desktop\flower-service\venv\lib\site-packages\django\contrib\auth\base_user.py", line 66, in save
    super().save(*args, **kwargs)

  File "C:\Users\项波\Desktop\flower-service\venv\lib\site-packages\django\db\models\base.py", line 741, in save
    force_update=force_update, update_fields=update_fields)

  File "C:\Users\项波\Desktop\flower-service\venv\lib\site-packages\django\db\models\base.py", line 779, in save_base
    force_update, using, update_fields,

  File "C:\Users\项波\Desktop\flower-service\venv\lib\site-packages\django\db\models\base.py", line 870, in _save_table
    result = self._do_insert(cls._base_manager, using, fields, update_pk, raw)

  File "C:\Users\项波\Desktop\flower-service\venv\lib\site-packages\django\db\models\base.py", line 908, in _do_insert
    using=using, raw=raw)

  File "C:\Users\项波\Desktop\flower-service\venv\lib\site-packages\django\db\models\manager.py", line 82, in manager_method
    return getattr(self.get_queryset(), name)(*args, **kwargs)

  File "C:\Users\项波\Desktop\flower-service\venv\lib\site-packages\django\db\models\query.py", line 1186, in _insert
    return query.get_compiler(using=using).execute_sql(return_id)

  File "C:\Users\项波\Desktop\flower-service\venv\lib\site-packages\django\db\models\sql\compiler.py", line 1335, in execute_sql
    cursor.execute(sql, params)

  File "C:\Users\项波\Desktop\flower-service\venv\lib\site-packages\django\db\backends\utils.py", line 99, in execute
    return super().execute(sql, params)

  File "C:\Users\项波\Desktop\flower-service\venv\lib\site-packages\django\db\backends\utils.py", line 67, in execute
    return self._execute_with_wrappers(sql, params, many=False, executor=self._execute)

  File "C:\Users\项波\Desktop\flower-service\venv\lib\site-packages\django\db\backends\utils.py", line 76, in _execute_with_wrappers
    return executor(sql, params, many, context)

  File "C:\Users\项波\Desktop\flower-service\venv\lib\site-packages\django\db\backends\utils.py", line 84, in _execute
    return self.cursor.execute(sql, params)

  File "C:\Users\项波\Desktop\flower-service\venv\lib\site-packages\django\db\utils.py", line 89, in __exit__
    raise dj_exc_value.with_traceback(traceback) from exc_value

  File "C:\Users\项波\Desktop\flower-service\venv\lib\site-packages\django\db\backends\utils.py", line 84, in _execute
    return self.cursor.execute(sql, params)

  File "C:\Users\项波\Desktop\flower-service\venv\lib\site-packages\django\db\backends\mysql\base.py", line 71, in execute
    return self.cursor.execute(query, args)

  File "C:\Users\项波\Desktop\flower-service\venv\lib\site-packages\pymysql\cursors.py", line 170, in execute
    result = self._query(query)

  File "C:\Users\项波\Desktop\flower-service\venv\lib\site-packages\pymysql\cursors.py", line 328, in _query
    conn.query(q)

  File "C:\Users\项波\Desktop\flower-service\venv\lib\site-packages\pymysql\connections.py", line 517, in query
    self._affected_rows = self._read_query_result(unbuffered=unbuffered)

  File "C:\Users\项波\Desktop\flower-service\venv\lib\site-packages\pymysql\connections.py", line 732, in _read_query_result
    result.read()

  File "C:\Users\项波\Desktop\flower-service\venv\lib\site-packages\pymysql\connections.py", line 1075, in read
    first_packet = self.connection._read_packet()

  File "C:\Users\项波\Desktop\flower-service\venv\lib\site-packages\pymysql\connections.py", line 684, in _read_packet
    packet.check_error()

  File "C:\Users\项波\Desktop\flower-service\venv\lib\site-packages\pymysql\protocol.py", line 220, in check_error
    err.raise_mysql_exception(self._data)

  File "C:\Users\项波\Desktop\flower-service\venv\lib\site-packages\pymysql\err.py", line 109, in raise_mysql_exception
    raise errorclass(errno, errval)

django.db.utils.IntegrityError: (1062, "Duplicate entry 'oV4sn4198XxyV91iEuSL5NJBg0p4' for key 'openid'")

}}}

{{{
<WSGIRequest: POST '/api/account/login/'>
}}}
Traceback (most recent call last):
  File "C:\Users\项波\Desktop\flower-service\venv\lib\site-packages\django\db\models\query.py", line 538, in get_or_create
    return self.get(**kwargs), False
  File "C:\Users\项波\Desktop\flower-service\venv\lib\site-packages\django\db\models\query.py", line 408, in get
    self.model._meta.object_name
account.models.MyUser.DoesNotExist: MyUser matching query does not exist.

During handling of the above exception, another exception occurred:

Traceback (most recent call last):
  File "C:\Users\项波\Desktop\flower-service\venv\lib\site-packages\django\db\backends\utils.py", line 84, in _execute
    return self.cursor.execute(sql, params)
  File "C:\Users\项波\Desktop\flower-service\venv\lib\site-packages\django\db\backends\mysql\base.py", line 71, in execute
    return self.cursor.execute(query, args)
  File "C:\Users\项波\Desktop\flower-service\venv\lib\site-packages\pymysql\cursors.py", line 170, in execute
    result = self._query(query)
  File "C:\Users\项波\Desktop\flower-service\venv\lib\site-packages\pymysql\cursors.py", line 328, in _query
    conn.query(q)
  File "C:\Users\项波\Desktop\flower-service\venv\lib\site-packages\pymysql\connections.py", line 517, in query
    self._affected_rows = self._read_query_result(unbuffered=unbuffered)
  File "C:\Users\项波\Desktop\flower-service\venv\lib\site-packages\pymysql\connections.py", line 732, in _read_query_result
    result.read()
  File "C:\Users\项波\Desktop\flower-service\venv\lib\site-packages\pymysql\connections.py", line 1075, in read
    first_packet = self.connection._read_packet()
  File "C:\Users\项波\Desktop\flower-service\venv\lib\site-packages\pymysql\connections.py", line 684, in _read_packet
    packet.check_error()
  File "C:\Users\项波\Desktop\flower-service\venv\lib\site-packages\pymysql\protocol.py", line 220, in check_error
    err.raise_mysql_exception(self._data)
  File "C:\Users\项波\Desktop\flower-service\venv\lib\site-packages\pymysql\err.py", line 109, in raise_mysql_exception
    raise errorclass(errno, errval)
pymysql.err.IntegrityError: (1062, "Duplicate entry 'oV4sn4198XxyV91iEuSL5NJBg0p4' for key 'openid'")

The above exception was the direct cause of the following exception:

Traceback (most recent call last):
  File "C:\Users\项波\Desktop\flower-service\venv\lib\site-packages\django\core\handlers\base.py", line 113, in _get_response
    response = wrapped_callback(request, *callback_args, **callback_kwargs)
  File "C:\Users\项波\Desktop\flower-service\venv\lib\site-packages\django\views\decorators\csrf.py", line 54, in wrapped_view
    return view_func(*args, **kwargs)
  File "C:\Users\项波\Desktop\flower-service\venv\lib\site-packages\django\views\generic\base.py", line 71, in view
    return self.dispatch(request, *args, **kwargs)
  File "C:\Users\项波\Desktop\flower-service\venv\lib\site-packages\rest_framework\views.py", line 497, in dispatch
    response = self.handle_exception(exc)
  File "C:\Users\项波\Desktop\flower-service\venv\lib\site-packages\rest_framework\views.py", line 457, in handle_exception
    self.raise_uncaught_exception(exc)
  File "C:\Users\项波\Desktop\flower-service\venv\lib\site-packages\rest_framework\views.py", line 468, in raise_uncaught_exception
    raise exc
  File "C:\Users\项波\Desktop\flower-service\venv\lib\site-packages\rest_framework\views.py", line 494, in dispatch
    response = handler(request, *args, **kwargs)
  File "C:\Users\项波\Desktop\flower-service\src\apps\common\decorator.py", line 17, in _func
    resp = func(*args, **kwargs)
  File "C:\Users\项波\Desktop\flower-service\src\apps\account\apis.py", line 51, in post
    user_lastip=user_ip,
  File "C:\Users\项波\Desktop\flower-service\venv\lib\site-packages\django\db\models\manager.py", line 82, in manager_method
    return getattr(self.get_queryset(), name)(*args, **kwargs)
  File "C:\Users\项波\Desktop\flower-service\venv\lib\site-packages\django\db\models\query.py", line 541, in get_or_create
    return self._create_object_from_params(kwargs, params)
  File "C:\Users\项波\Desktop\flower-service\venv\lib\site-packages\django\db\models\query.py", line 583, in _create_object_from_params
    raise e
  File "C:\Users\项波\Desktop\flower-service\venv\lib\site-packages\django\db\models\query.py", line 575, in _create_object_from_params
    obj = self.create(**params)
  File "C:\Users\项波\Desktop\flower-service\venv\lib\site-packages\django\db\models\query.py", line 422, in create
    obj.save(force_insert=True, using=self.db)
  File "C:\Users\项波\Desktop\flower-service\venv\lib\site-packages\django\contrib\auth\base_user.py", line 66, in save
    super().save(*args, **kwargs)
  File "C:\Users\项波\Desktop\flower-service\venv\lib\site-packages\django\db\models\base.py", line 741, in save
    force_update=force_update, update_fields=update_fields)
  File "C:\Users\项波\Desktop\flower-service\venv\lib\site-packages\django\db\models\base.py", line 779, in save_base
    force_update, using, update_fields,
  File "C:\Users\项波\Desktop\flower-service\venv\lib\site-packages\django\db\models\base.py", line 870, in _save_table
    result = self._do_insert(cls._base_manager, using, fields, update_pk, raw)
  File "C:\Users\项波\Desktop\flower-service\venv\lib\site-packages\django\db\models\base.py", line 908, in _do_insert
    using=using, raw=raw)
  File "C:\Users\项波\Desktop\flower-service\venv\lib\site-packages\django\db\models\manager.py", line 82, in manager_method
    return getattr(self.get_queryset(), name)(*args, **kwargs)
  File "C:\Users\项波\Desktop\flower-service\venv\lib\site-packages\django\db\models\query.py", line 1186, in _insert
    return query.get_compiler(using=using).execute_sql(return_id)
  File "C:\Users\项波\Desktop\flower-service\venv\lib\site-packages\django\db\models\sql\compiler.py", line 1335, in execute_sql
    cursor.execute(sql, params)
  File "C:\Users\项波\Desktop\flower-service\venv\lib\site-packages\django\db\backends\utils.py", line 99, in execute
    return super().execute(sql, params)
  File "C:\Users\项波\Desktop\flower-service\venv\lib\site-packages\django\db\backends\utils.py", line 67, in execute
    return self._execute_with_wrappers(sql, params, many=False, executor=self._execute)
  File "C:\Users\项波\Desktop\flower-service\venv\lib\site-packages\django\db\backends\utils.py", line 76, in _execute_with_wrappers
    return executor(sql, params, many, context)
  File "C:\Users\项波\Desktop\flower-service\venv\lib\site-packages\django\db\backends\utils.py", line 84, in _execute
    return self.cursor.execute(sql, params)
  File "C:\Users\项波\Desktop\flower-service\venv\lib\site-packages\django\db\utils.py", line 89, in __exit__
    raise dj_exc_value.with_traceback(traceback) from exc_value
  File "C:\Users\项波\Desktop\flower-service\venv\lib\site-packages\django\db\backends\utils.py", line 84, in _execute
    return self.cursor.execute(sql, params)
  File "C:\Users\项波\Desktop\flower-service\venv\lib\site-packages\django\db\backends\mysql\base.py", line 71, in execute
    return self.cursor.execute(query, args)
  File "C:\Users\项波\Desktop\flower-service\venv\lib\site-packages\pymysql\cursors.py", line 170, in execute
    result = self._query(query)
  File "C:\Users\项波\Desktop\flower-service\venv\lib\site-packages\pymysql\cursors.py", line 328, in _query
    conn.query(q)
  File "C:\Users\项波\Desktop\flower-service\venv\lib\site-packages\pymysql\connections.py", line 517, in query
    self._affected_rows = self._read_query_result(unbuffered=unbuffered)
  File "C:\Users\项波\Desktop\flower-service\venv\lib\site-packages\pymysql\connections.py", line 732, in _read_query_result
    result.read()
  File "C:\Users\项波\Desktop\flower-service\venv\lib\site-packages\pymysql\connections.py", line 1075, in read
    first_packet = self.connection._read_packet()
  File "C:\Users\项波\Desktop\flower-service\venv\lib\site-packages\pymysql\connections.py", line 684, in _read_packet
    packet.check_error()
  File "C:\Users\项波\Desktop\flower-service\venv\lib\site-packages\pymysql\protocol.py", line 220, in check_error
    err.raise_mysql_exception(self._data)
  File "C:\Users\项波\Desktop\flower-service\venv\lib\site-packages\pymysql\err.py", line 109, in raise_mysql_exception
    raise errorclass(errno, errval)
django.db.utils.IntegrityError: (1062, "Duplicate entry 'oV4sn4198XxyV91iEuSL5NJBg0p4' for key 'openid'")
2019-09-01 22:06:31,604 [Thread-3:6112] [service_mart.common.decorator:52] [ERROR]- error:error response:'Request' object has no attribute 'Meta'
2019-09-01 22:06:31,606 [Thread-3:6112] [service_mart.helper.middleware:163] [ERROR]- {{{
Traceback (most recent call last):

  File "C:\Users\项波\Desktop\flower-service\venv\lib\site-packages\rest_framework\request.py", line 409, in __getattr__
    return getattr(self._request, attr)

AttributeError: 'WSGIRequest' object has no attribute 'Meta'


During handling of the above exception, another exception occurred:


Traceback (most recent call last):

  File "C:\Users\项波\Desktop\flower-service\venv\lib\site-packages\django\core\handlers\base.py", line 113, in _get_response
    response = wrapped_callback(request, *callback_args, **callback_kwargs)

  File "C:\Users\项波\Desktop\flower-service\venv\lib\site-packages\django\views\decorators\csrf.py", line 54, in wrapped_view
    return view_func(*args, **kwargs)

  File "C:\Users\项波\Desktop\flower-service\venv\lib\site-packages\django\views\generic\base.py", line 71, in view
    return self.dispatch(request, *args, **kwargs)

  File "C:\Users\项波\Desktop\flower-service\venv\lib\site-packages\rest_framework\views.py", line 497, in dispatch
    response = self.handle_exception(exc)

  File "C:\Users\项波\Desktop\flower-service\venv\lib\site-packages\rest_framework\views.py", line 457, in handle_exception
    self.raise_uncaught_exception(exc)

  File "C:\Users\项波\Desktop\flower-service\venv\lib\site-packages\rest_framework\views.py", line 468, in raise_uncaught_exception
    raise exc

  File "C:\Users\项波\Desktop\flower-service\venv\lib\site-packages\rest_framework\views.py", line 494, in dispatch
    response = handler(request, *args, **kwargs)

  File "C:\Users\项波\Desktop\flower-service\src\apps\common\decorator.py", line 17, in _func
    resp = func(*args, **kwargs)

  File "C:\Users\项波\Desktop\flower-service\src\apps\account\apis.py", line 116, in put
    print(request.auth, request.user.id, request.Meta.get('Authorization'))

  File "C:\Users\项波\Desktop\flower-service\venv\lib\site-packages\rest_framework\request.py", line 411, in __getattr__
    return self.__getattribute__(attr)

AttributeError: 'Request' object has no attribute 'Meta'

}}}

{{{
<WSGIRequest: PUT '/api/account/userInfo/'>
}}}
Traceback (most recent call last):
  File "C:\Users\项波\Desktop\flower-service\venv\lib\site-packages\rest_framework\request.py", line 409, in __getattr__
    return getattr(self._request, attr)
AttributeError: 'WSGIRequest' object has no attribute 'Meta'

During handling of the above exception, another exception occurred:

Traceback (most recent call last):
  File "C:\Users\项波\Desktop\flower-service\venv\lib\site-packages\django\core\handlers\base.py", line 113, in _get_response
    response = wrapped_callback(request, *callback_args, **callback_kwargs)
  File "C:\Users\项波\Desktop\flower-service\venv\lib\site-packages\django\views\decorators\csrf.py", line 54, in wrapped_view
    return view_func(*args, **kwargs)
  File "C:\Users\项波\Desktop\flower-service\venv\lib\site-packages\django\views\generic\base.py", line 71, in view
    return self.dispatch(request, *args, **kwargs)
  File "C:\Users\项波\Desktop\flower-service\venv\lib\site-packages\rest_framework\views.py", line 497, in dispatch
    response = self.handle_exception(exc)
  File "C:\Users\项波\Desktop\flower-service\venv\lib\site-packages\rest_framework\views.py", line 457, in handle_exception
    self.raise_uncaught_exception(exc)
  File "C:\Users\项波\Desktop\flower-service\venv\lib\site-packages\rest_framework\views.py", line 468, in raise_uncaught_exception
    raise exc
  File "C:\Users\项波\Desktop\flower-service\venv\lib\site-packages\rest_framework\views.py", line 494, in dispatch
    response = handler(request, *args, **kwargs)
  File "C:\Users\项波\Desktop\flower-service\src\apps\common\decorator.py", line 17, in _func
    resp = func(*args, **kwargs)
  File "C:\Users\项波\Desktop\flower-service\src\apps\account\apis.py", line 116, in put
    print(request.auth, request.user.id, request.Meta.get('Authorization'))
  File "C:\Users\项波\Desktop\flower-service\venv\lib\site-packages\rest_framework\request.py", line 411, in __getattr__
    return self.__getattribute__(attr)
AttributeError: 'Request' object has no attribute 'Meta'
2019-09-01 22:06:49,431 [Thread-1:8552] [service_mart.common.decorator:52] [ERROR]- error:error response:'Request' object has no attribute 'Meta'
2019-09-01 22:06:49,432 [Thread-1:8552] [service_mart.helper.middleware:163] [ERROR]- {{{
Traceback (most recent call last):

  File "C:\Users\项波\Desktop\flower-service\venv\lib\site-packages\rest_framework\request.py", line 409, in __getattr__
    return getattr(self._request, attr)

AttributeError: 'WSGIRequest' object has no attribute 'Meta'


During handling of the above exception, another exception occurred:


Traceback (most recent call last):

  File "C:\Users\项波\Desktop\flower-service\venv\lib\site-packages\django\core\handlers\base.py", line 113, in _get_response
    response = wrapped_callback(request, *callback_args, **callback_kwargs)

  File "C:\Users\项波\Desktop\flower-service\venv\lib\site-packages\django\views\decorators\csrf.py", line 54, in wrapped_view
    return view_func(*args, **kwargs)

  File "C:\Users\项波\Desktop\flower-service\venv\lib\site-packages\django\views\generic\base.py", line 71, in view
    return self.dispatch(request, *args, **kwargs)

  File "C:\Users\项波\Desktop\flower-service\venv\lib\site-packages\rest_framework\views.py", line 497, in dispatch
    response = self.handle_exception(exc)

  File "C:\Users\项波\Desktop\flower-service\venv\lib\site-packages\rest_framework\views.py", line 457, in handle_exception
    self.raise_uncaught_exception(exc)

  File "C:\Users\项波\Desktop\flower-service\venv\lib\site-packages\rest_framework\views.py", line 468, in raise_uncaught_exception
    raise exc

  File "C:\Users\项波\Desktop\flower-service\venv\lib\site-packages\rest_framework\views.py", line 494, in dispatch
    response = handler(request, *args, **kwargs)

  File "C:\Users\项波\Desktop\flower-service\src\apps\common\decorator.py", line 17, in _func
    resp = func(*args, **kwargs)

  File "C:\Users\项波\Desktop\flower-service\src\apps\account\apis.py", line 116, in put
    print(request.auth, request.user.id, self.request.Meta.get('Authorization'))

  File "C:\Users\项波\Desktop\flower-service\venv\lib\site-packages\rest_framework\request.py", line 411, in __getattr__
    return self.__getattribute__(attr)

AttributeError: 'Request' object has no attribute 'Meta'

}}}

{{{
<WSGIRequest: PUT '/api/account/userInfo/'>
}}}
Traceback (most recent call last):
  File "C:\Users\项波\Desktop\flower-service\venv\lib\site-packages\rest_framework\request.py", line 409, in __getattr__
    return getattr(self._request, attr)
AttributeError: 'WSGIRequest' object has no attribute 'Meta'

During handling of the above exception, another exception occurred:

Traceback (most recent call last):
  File "C:\Users\项波\Desktop\flower-service\venv\lib\site-packages\django\core\handlers\base.py", line 113, in _get_response
    response = wrapped_callback(request, *callback_args, **callback_kwargs)
  File "C:\Users\项波\Desktop\flower-service\venv\lib\site-packages\django\views\decorators\csrf.py", line 54, in wrapped_view
    return view_func(*args, **kwargs)
  File "C:\Users\项波\Desktop\flower-service\venv\lib\site-packages\django\views\generic\base.py", line 71, in view
    return self.dispatch(request, *args, **kwargs)
  File "C:\Users\项波\Desktop\flower-service\venv\lib\site-packages\rest_framework\views.py", line 497, in dispatch
    response = self.handle_exception(exc)
  File "C:\Users\项波\Desktop\flower-service\venv\lib\site-packages\rest_framework\views.py", line 457, in handle_exception
    self.raise_uncaught_exception(exc)
  File "C:\Users\项波\Desktop\flower-service\venv\lib\site-packages\rest_framework\views.py", line 468, in raise_uncaught_exception
    raise exc
  File "C:\Users\项波\Desktop\flower-service\venv\lib\site-packages\rest_framework\views.py", line 494, in dispatch
    response = handler(request, *args, **kwargs)
  File "C:\Users\项波\Desktop\flower-service\src\apps\common\decorator.py", line 17, in _func
    resp = func(*args, **kwargs)
  File "C:\Users\项波\Desktop\flower-service\src\apps\account\apis.py", line 116, in put
    print(request.auth, request.user.id, self.request.Meta.get('Authorization'))
  File "C:\Users\项波\Desktop\flower-service\venv\lib\site-packages\rest_framework\request.py", line 411, in __getattr__
    return self.__getattribute__(attr)
AttributeError: 'Request' object has no attribute 'Meta'
2019-09-01 22:10:18,356 [Thread-1:7228] [service_mart.common.decorator:52] [ERROR]- error:error response:'Authorization'
2019-09-01 22:10:18,357 [Thread-1:7228] [service_mart.helper.middleware:163] [ERROR]- {{{
Traceback (most recent call last):

  File "C:\Users\项波\Desktop\flower-service\venv\lib\site-packages\django\core\handlers\base.py", line 113, in _get_response
    response = wrapped_callback(request, *callback_args, **callback_kwargs)

  File "C:\Users\项波\Desktop\flower-service\venv\lib\site-packages\django\views\decorators\csrf.py", line 54, in wrapped_view
    return view_func(*args, **kwargs)

  File "C:\Users\项波\Desktop\flower-service\venv\lib\site-packages\django\views\generic\base.py", line 71, in view
    return self.dispatch(request, *args, **kwargs)

  File "C:\Users\项波\Desktop\flower-service\venv\lib\site-packages\rest_framework\views.py", line 497, in dispatch
    response = self.handle_exception(exc)

  File "C:\Users\项波\Desktop\flower-service\venv\lib\site-packages\rest_framework\views.py", line 457, in handle_exception
    self.raise_uncaught_exception(exc)

  File "C:\Users\项波\Desktop\flower-service\venv\lib\site-packages\rest_framework\views.py", line 468, in raise_uncaught_exception
    raise exc

  File "C:\Users\项波\Desktop\flower-service\venv\lib\site-packages\rest_framework\views.py", line 494, in dispatch
    response = handler(request, *args, **kwargs)

  File "C:\Users\项波\Desktop\flower-service\src\apps\common\decorator.py", line 17, in _func
    resp = func(*args, **kwargs)

  File "C:\Users\项波\Desktop\flower-service\src\apps\account\apis.py", line 118, in put
    token = self.request.META['Authorization']

KeyError: 'Authorization'

}}}

{{{
<WSGIRequest: PUT '/api/account/userInfo/'>
}}}
Traceback (most recent call last):
  File "C:\Users\项波\Desktop\flower-service\venv\lib\site-packages\django\core\handlers\base.py", line 113, in _get_response
    response = wrapped_callback(request, *callback_args, **callback_kwargs)
  File "C:\Users\项波\Desktop\flower-service\venv\lib\site-packages\django\views\decorators\csrf.py", line 54, in wrapped_view
    return view_func(*args, **kwargs)
  File "C:\Users\项波\Desktop\flower-service\venv\lib\site-packages\django\views\generic\base.py", line 71, in view
    return self.dispatch(request, *args, **kwargs)
  File "C:\Users\项波\Desktop\flower-service\venv\lib\site-packages\rest_framework\views.py", line 497, in dispatch
    response = self.handle_exception(exc)
  File "C:\Users\项波\Desktop\flower-service\venv\lib\site-packages\rest_framework\views.py", line 457, in handle_exception
    self.raise_uncaught_exception(exc)
  File "C:\Users\项波\Desktop\flower-service\venv\lib\site-packages\rest_framework\views.py", line 468, in raise_uncaught_exception
    raise exc
  File "C:\Users\项波\Desktop\flower-service\venv\lib\site-packages\rest_framework\views.py", line 494, in dispatch
    response = handler(request, *args, **kwargs)
  File "C:\Users\项波\Desktop\flower-service\src\apps\common\decorator.py", line 17, in _func
    resp = func(*args, **kwargs)
  File "C:\Users\项波\Desktop\flower-service\src\apps\account\apis.py", line 118, in put
    token = self.request.META['Authorization']
KeyError: 'Authorization'
2019-09-01 22:10:43,377 [Thread-4:980] [service_mart.common.decorator:52] [ERROR]- error:error response:Invalid header padding
2019-09-01 22:10:43,381 [Thread-4:980] [service_mart.helper.middleware:163] [ERROR]- {{{
Traceback (most recent call last):

  File "C:\Users\项波\Desktop\flower-service\venv\lib\site-packages\jwt\api_jws.py", line 186, in _load
    header_data = base64url_decode(header_segment)

  File "C:\Users\项波\Desktop\flower-service\venv\lib\site-packages\jwt\utils.py", line 42, in base64url_decode
    return base64.urlsafe_b64decode(input)

  File "C:\Users\项波\AppData\Local\Programs\Python\Python36\lib\base64.py", line 133, in urlsafe_b64decode
    return b64decode(s)

  File "C:\Users\项波\AppData\Local\Programs\Python\Python36\lib\base64.py", line 87, in b64decode
    return binascii.a2b_base64(s)

binascii.Error: Incorrect padding


During handling of the above exception, another exception occurred:


Traceback (most recent call last):

  File "C:\Users\项波\Desktop\flower-service\venv\lib\site-packages\django\core\handlers\base.py", line 113, in _get_response
    response = wrapped_callback(request, *callback_args, **callback_kwargs)

  File "C:\Users\项波\Desktop\flower-service\venv\lib\site-packages\django\views\decorators\csrf.py", line 54, in wrapped_view
    return view_func(*args, **kwargs)

  File "C:\Users\项波\Desktop\flower-service\venv\lib\site-packages\django\views\generic\base.py", line 71, in view
    return self.dispatch(request, *args, **kwargs)

  File "C:\Users\项波\Desktop\flower-service\venv\lib\site-packages\rest_framework\views.py", line 497, in dispatch
    response = self.handle_exception(exc)

  File "C:\Users\项波\Desktop\flower-service\venv\lib\site-packages\rest_framework\views.py", line 457, in handle_exception
    self.raise_uncaught_exception(exc)

  File "C:\Users\项波\Desktop\flower-service\venv\lib\site-packages\rest_framework\views.py", line 468, in raise_uncaught_exception
    raise exc

  File "C:\Users\项波\Desktop\flower-service\venv\lib\site-packages\rest_framework\views.py", line 494, in dispatch
    response = handler(request, *args, **kwargs)

  File "C:\Users\项波\Desktop\flower-service\src\apps\common\decorator.py", line 17, in _func
    resp = func(*args, **kwargs)

  File "C:\Users\项波\Desktop\flower-service\src\apps\account\apis.py", line 119, in put
    print(jwt_decode_handler(token))

  File "C:\Users\项波\Desktop\flower-service\venv\lib\site-packages\rest_framework_jwt\utils.py", line 104, in jwt_decode_handler
    unverified_payload = jwt.decode(token, None, False)

  File "C:\Users\项波\Desktop\flower-service\venv\lib\site-packages\jwt\api_jwt.py", line 84, in decode
    payload, _, _, _ = self._load(jwt)

  File "C:\Users\项波\Desktop\flower-service\venv\lib\site-packages\jwt\api_jws.py", line 188, in _load
    raise DecodeError('Invalid header padding')

jwt.exceptions.DecodeError: Invalid header padding

}}}

{{{
<WSGIRequest: PUT '/api/account/userInfo/'>
}}}
Traceback (most recent call last):
  File "C:\Users\项波\Desktop\flower-service\venv\lib\site-packages\jwt\api_jws.py", line 186, in _load
    header_data = base64url_decode(header_segment)
  File "C:\Users\项波\Desktop\flower-service\venv\lib\site-packages\jwt\utils.py", line 42, in base64url_decode
    return base64.urlsafe_b64decode(input)
  File "C:\Users\项波\AppData\Local\Programs\Python\Python36\lib\base64.py", line 133, in urlsafe_b64decode
    return b64decode(s)
  File "C:\Users\项波\AppData\Local\Programs\Python\Python36\lib\base64.py", line 87, in b64decode
    return binascii.a2b_base64(s)
binascii.Error: Incorrect padding

During handling of the above exception, another exception occurred:

Traceback (most recent call last):
  File "C:\Users\项波\Desktop\flower-service\venv\lib\site-packages\django\core\handlers\base.py", line 113, in _get_response
    response = wrapped_callback(request, *callback_args, **callback_kwargs)
  File "C:\Users\项波\Desktop\flower-service\venv\lib\site-packages\django\views\decorators\csrf.py", line 54, in wrapped_view
    return view_func(*args, **kwargs)
  File "C:\Users\项波\Desktop\flower-service\venv\lib\site-packages\django\views\generic\base.py", line 71, in view
    return self.dispatch(request, *args, **kwargs)
  File "C:\Users\项波\Desktop\flower-service\venv\lib\site-packages\rest_framework\views.py", line 497, in dispatch
    response = self.handle_exception(exc)
  File "C:\Users\项波\Desktop\flower-service\venv\lib\site-packages\rest_framework\views.py", line 457, in handle_exception
    self.raise_uncaught_exception(exc)
  File "C:\Users\项波\Desktop\flower-service\venv\lib\site-packages\rest_framework\views.py", line 468, in raise_uncaught_exception
    raise exc
  File "C:\Users\项波\Desktop\flower-service\venv\lib\site-packages\rest_framework\views.py", line 494, in dispatch
    response = handler(request, *args, **kwargs)
  File "C:\Users\项波\Desktop\flower-service\src\apps\common\decorator.py", line 17, in _func
    resp = func(*args, **kwargs)
  File "C:\Users\项波\Desktop\flower-service\src\apps\account\apis.py", line 119, in put
    print(jwt_decode_handler(token))
  File "C:\Users\项波\Desktop\flower-service\venv\lib\site-packages\rest_framework_jwt\utils.py", line 104, in jwt_decode_handler
    unverified_payload = jwt.decode(token, None, False)
  File "C:\Users\项波\Desktop\flower-service\venv\lib\site-packages\jwt\api_jwt.py", line 84, in decode
    payload, _, _, _ = self._load(jwt)
  File "C:\Users\项波\Desktop\flower-service\venv\lib\site-packages\jwt\api_jws.py", line 188, in _load
    raise DecodeError('Invalid header padding')
jwt.exceptions.DecodeError: Invalid header padding
2019-09-01 22:11:51,431 [Thread-1:5952] [service_mart.common.decorator:52] [ERROR]- error:error response:Invalid header padding
2019-09-01 22:11:51,433 [Thread-1:5952] [service_mart.helper.middleware:163] [ERROR]- {{{
Traceback (most recent call last):

  File "C:\Users\项波\Desktop\flower-service\venv\lib\site-packages\jwt\api_jws.py", line 186, in _load
    header_data = base64url_decode(header_segment)

  File "C:\Users\项波\Desktop\flower-service\venv\lib\site-packages\jwt\utils.py", line 42, in base64url_decode
    return base64.urlsafe_b64decode(input)

  File "C:\Users\项波\AppData\Local\Programs\Python\Python36\lib\base64.py", line 133, in urlsafe_b64decode
    return b64decode(s)

  File "C:\Users\项波\AppData\Local\Programs\Python\Python36\lib\base64.py", line 87, in b64decode
    return binascii.a2b_base64(s)

binascii.Error: Incorrect padding


During handling of the above exception, another exception occurred:


Traceback (most recent call last):

  File "C:\Users\项波\Desktop\flower-service\venv\lib\site-packages\django\core\handlers\base.py", line 113, in _get_response
    response = wrapped_callback(request, *callback_args, **callback_kwargs)

  File "C:\Users\项波\Desktop\flower-service\venv\lib\site-packages\django\views\decorators\csrf.py", line 54, in wrapped_view
    return view_func(*args, **kwargs)

  File "C:\Users\项波\Desktop\flower-service\venv\lib\site-packages\django\views\generic\base.py", line 71, in view
    return self.dispatch(request, *args, **kwargs)

  File "C:\Users\项波\Desktop\flower-service\venv\lib\site-packages\rest_framework\views.py", line 497, in dispatch
    response = self.handle_exception(exc)

  File "C:\Users\项波\Desktop\flower-service\venv\lib\site-packages\rest_framework\views.py", line 457, in handle_exception
    self.raise_uncaught_exception(exc)

  File "C:\Users\项波\Desktop\flower-service\venv\lib\site-packages\rest_framework\views.py", line 468, in raise_uncaught_exception
    raise exc

  File "C:\Users\项波\Desktop\flower-service\venv\lib\site-packages\rest_framework\views.py", line 494, in dispatch
    response = handler(request, *args, **kwargs)

  File "C:\Users\项波\Desktop\flower-service\src\apps\common\decorator.py", line 17, in _func
    resp = func(*args, **kwargs)

  File "C:\Users\项波\Desktop\flower-service\src\apps\account\apis.py", line 118, in put
    print(jwt_decode_handler(token))

  File "C:\Users\项波\Desktop\flower-service\venv\lib\site-packages\rest_framework_jwt\utils.py", line 104, in jwt_decode_handler
    unverified_payload = jwt.decode(token, None, False)

  File "C:\Users\项波\Desktop\flower-service\venv\lib\site-packages\jwt\api_jwt.py", line 84, in decode
    payload, _, _, _ = self._load(jwt)

  File "C:\Users\项波\Desktop\flower-service\venv\lib\site-packages\jwt\api_jws.py", line 188, in _load
    raise DecodeError('Invalid header padding')

jwt.exceptions.DecodeError: Invalid header padding

}}}

{{{
<WSGIRequest: PUT '/api/account/userInfo/'>
}}}
Traceback (most recent call last):
  File "C:\Users\项波\Desktop\flower-service\venv\lib\site-packages\jwt\api_jws.py", line 186, in _load
    header_data = base64url_decode(header_segment)
  File "C:\Users\项波\Desktop\flower-service\venv\lib\site-packages\jwt\utils.py", line 42, in base64url_decode
    return base64.urlsafe_b64decode(input)
  File "C:\Users\项波\AppData\Local\Programs\Python\Python36\lib\base64.py", line 133, in urlsafe_b64decode
    return b64decode(s)
  File "C:\Users\项波\AppData\Local\Programs\Python\Python36\lib\base64.py", line 87, in b64decode
    return binascii.a2b_base64(s)
binascii.Error: Incorrect padding

During handling of the above exception, another exception occurred:

Traceback (most recent call last):
  File "C:\Users\项波\Desktop\flower-service\venv\lib\site-packages\django\core\handlers\base.py", line 113, in _get_response
    response = wrapped_callback(request, *callback_args, **callback_kwargs)
  File "C:\Users\项波\Desktop\flower-service\venv\lib\site-packages\django\views\decorators\csrf.py", line 54, in wrapped_view
    return view_func(*args, **kwargs)
  File "C:\Users\项波\Desktop\flower-service\venv\lib\site-packages\django\views\generic\base.py", line 71, in view
    return self.dispatch(request, *args, **kwargs)
  File "C:\Users\项波\Desktop\flower-service\venv\lib\site-packages\rest_framework\views.py", line 497, in dispatch
    response = self.handle_exception(exc)
  File "C:\Users\项波\Desktop\flower-service\venv\lib\site-packages\rest_framework\views.py", line 457, in handle_exception
    self.raise_uncaught_exception(exc)
  File "C:\Users\项波\Desktop\flower-service\venv\lib\site-packages\rest_framework\views.py", line 468, in raise_uncaught_exception
    raise exc
  File "C:\Users\项波\Desktop\flower-service\venv\lib\site-packages\rest_framework\views.py", line 494, in dispatch
    response = handler(request, *args, **kwargs)
  File "C:\Users\项波\Desktop\flower-service\src\apps\common\decorator.py", line 17, in _func
    resp = func(*args, **kwargs)
  File "C:\Users\项波\Desktop\flower-service\src\apps\account\apis.py", line 118, in put
    print(jwt_decode_handler(token))
  File "C:\Users\项波\Desktop\flower-service\venv\lib\site-packages\rest_framework_jwt\utils.py", line 104, in jwt_decode_handler
    unverified_payload = jwt.decode(token, None, False)
  File "C:\Users\项波\Desktop\flower-service\venv\lib\site-packages\jwt\api_jwt.py", line 84, in decode
    payload, _, _, _ = self._load(jwt)
  File "C:\Users\项波\Desktop\flower-service\venv\lib\site-packages\jwt\api_jws.py", line 188, in _load
    raise DecodeError('Invalid header padding')
jwt.exceptions.DecodeError: Invalid header padding
2019-09-01 22:12:17,808 [Thread-4:3348] [service_mart.common.decorator:52] [ERROR]- error:error response:Invalid header padding
2019-09-01 22:12:17,810 [Thread-4:3348] [service_mart.helper.middleware:163] [ERROR]- {{{
Traceback (most recent call last):

  File "C:\Users\项波\Desktop\flower-service\venv\lib\site-packages\jwt\api_jws.py", line 186, in _load
    header_data = base64url_decode(header_segment)

  File "C:\Users\项波\Desktop\flower-service\venv\lib\site-packages\jwt\utils.py", line 42, in base64url_decode
    return base64.urlsafe_b64decode(input)

  File "C:\Users\项波\AppData\Local\Programs\Python\Python36\lib\base64.py", line 133, in urlsafe_b64decode
    return b64decode(s)

  File "C:\Users\项波\AppData\Local\Programs\Python\Python36\lib\base64.py", line 87, in b64decode
    return binascii.a2b_base64(s)

binascii.Error: Incorrect padding


During handling of the above exception, another exception occurred:


Traceback (most recent call last):

  File "C:\Users\项波\Desktop\flower-service\venv\lib\site-packages\django\core\handlers\base.py", line 113, in _get_response
    response = wrapped_callback(request, *callback_args, **callback_kwargs)

  File "C:\Users\项波\Desktop\flower-service\venv\lib\site-packages\django\views\decorators\csrf.py", line 54, in wrapped_view
    return view_func(*args, **kwargs)

  File "C:\Users\项波\Desktop\flower-service\venv\lib\site-packages\django\views\generic\base.py", line 71, in view
    return self.dispatch(request, *args, **kwargs)

  File "C:\Users\项波\Desktop\flower-service\venv\lib\site-packages\rest_framework\views.py", line 497, in dispatch
    response = self.handle_exception(exc)

  File "C:\Users\项波\Desktop\flower-service\venv\lib\site-packages\rest_framework\views.py", line 457, in handle_exception
    self.raise_uncaught_exception(exc)

  File "C:\Users\项波\Desktop\flower-service\venv\lib\site-packages\rest_framework\views.py", line 468, in raise_uncaught_exception
    raise exc

  File "C:\Users\项波\Desktop\flower-service\venv\lib\site-packages\rest_framework\views.py", line 494, in dispatch
    response = handler(request, *args, **kwargs)

  File "C:\Users\项波\Desktop\flower-service\src\apps\common\decorator.py", line 17, in _func
    resp = func(*args, **kwargs)

  File "C:\Users\项波\Desktop\flower-service\src\apps\account\apis.py", line 119, in put
    print(jwt_decode_handler(token))

  File "C:\Users\项波\Desktop\flower-service\venv\lib\site-packages\rest_framework_jwt\utils.py", line 104, in jwt_decode_handler
    unverified_payload = jwt.decode(token, None, False)

  File "C:\Users\项波\Desktop\flower-service\venv\lib\site-packages\jwt\api_jwt.py", line 84, in decode
    payload, _, _, _ = self._load(jwt)

  File "C:\Users\项波\Desktop\flower-service\venv\lib\site-packages\jwt\api_jws.py", line 188, in _load
    raise DecodeError('Invalid header padding')

jwt.exceptions.DecodeError: Invalid header padding

}}}

{{{
<WSGIRequest: PUT '/api/account/userInfo/'>
}}}
Traceback (most recent call last):
  File "C:\Users\项波\Desktop\flower-service\venv\lib\site-packages\jwt\api_jws.py", line 186, in _load
    header_data = base64url_decode(header_segment)
  File "C:\Users\项波\Desktop\flower-service\venv\lib\site-packages\jwt\utils.py", line 42, in base64url_decode
    return base64.urlsafe_b64decode(input)
  File "C:\Users\项波\AppData\Local\Programs\Python\Python36\lib\base64.py", line 133, in urlsafe_b64decode
    return b64decode(s)
  File "C:\Users\项波\AppData\Local\Programs\Python\Python36\lib\base64.py", line 87, in b64decode
    return binascii.a2b_base64(s)
binascii.Error: Incorrect padding

During handling of the above exception, another exception occurred:

Traceback (most recent call last):
  File "C:\Users\项波\Desktop\flower-service\venv\lib\site-packages\django\core\handlers\base.py", line 113, in _get_response
    response = wrapped_callback(request, *callback_args, **callback_kwargs)
  File "C:\Users\项波\Desktop\flower-service\venv\lib\site-packages\django\views\decorators\csrf.py", line 54, in wrapped_view
    return view_func(*args, **kwargs)
  File "C:\Users\项波\Desktop\flower-service\venv\lib\site-packages\django\views\generic\base.py", line 71, in view
    return self.dispatch(request, *args, **kwargs)
  File "C:\Users\项波\Desktop\flower-service\venv\lib\site-packages\rest_framework\views.py", line 497, in dispatch
    response = self.handle_exception(exc)
  File "C:\Users\项波\Desktop\flower-service\venv\lib\site-packages\rest_framework\views.py", line 457, in handle_exception
    self.raise_uncaught_exception(exc)
  File "C:\Users\项波\Desktop\flower-service\venv\lib\site-packages\rest_framework\views.py", line 468, in raise_uncaught_exception
    raise exc
  File "C:\Users\项波\Desktop\flower-service\venv\lib\site-packages\rest_framework\views.py", line 494, in dispatch
    response = handler(request, *args, **kwargs)
  File "C:\Users\项波\Desktop\flower-service\src\apps\common\decorator.py", line 17, in _func
    resp = func(*args, **kwargs)
  File "C:\Users\项波\Desktop\flower-service\src\apps\account\apis.py", line 119, in put
    print(jwt_decode_handler(token))
  File "C:\Users\项波\Desktop\flower-service\venv\lib\site-packages\rest_framework_jwt\utils.py", line 104, in jwt_decode_handler
    unverified_payload = jwt.decode(token, None, False)
  File "C:\Users\项波\Desktop\flower-service\venv\lib\site-packages\jwt\api_jwt.py", line 84, in decode
    payload, _, _, _ = self._load(jwt)
  File "C:\Users\项波\Desktop\flower-service\venv\lib\site-packages\jwt\api_jws.py", line 188, in _load
    raise DecodeError('Invalid header padding')
jwt.exceptions.DecodeError: Invalid header padding
2019-09-01 22:26:01,395 [Thread-3:11588] [service_mart.common.decorator:52] [ERROR]- error:error response:'dict' object has no attribute 'id'
2019-09-01 22:26:01,396 [Thread-3:11588] [service_mart.helper.middleware:163] [ERROR]- {{{
Traceback (most recent call last):

  File "C:\Users\项波\Desktop\flower-service\venv\lib\site-packages\django\core\handlers\base.py", line 113, in _get_response
    response = wrapped_callback(request, *callback_args, **callback_kwargs)

  File "C:\Users\项波\Desktop\flower-service\venv\lib\site-packages\django\views\decorators\csrf.py", line 54, in wrapped_view
    return view_func(*args, **kwargs)

  File "C:\Users\项波\Desktop\flower-service\venv\lib\site-packages\django\views\generic\base.py", line 71, in view
    return self.dispatch(request, *args, **kwargs)

  File "C:\Users\项波\Desktop\flower-service\venv\lib\site-packages\rest_framework\views.py", line 497, in dispatch
    response = self.handle_exception(exc)

  File "C:\Users\项波\Desktop\flower-service\venv\lib\site-packages\rest_framework\views.py", line 457, in handle_exception
    self.raise_uncaught_exception(exc)

  File "C:\Users\项波\Desktop\flower-service\venv\lib\site-packages\rest_framework\views.py", line 468, in raise_uncaught_exception
    raise exc

  File "C:\Users\项波\Desktop\flower-service\venv\lib\site-packages\rest_framework\views.py", line 494, in dispatch
    response = handler(request, *args, **kwargs)

  File "C:\Users\项波\Desktop\flower-service\src\apps\common\decorator.py", line 17, in _func
    resp = func(*args, **kwargs)

  File "C:\Users\项波\Desktop\flower-service\src\apps\account\apis.py", line 118, in put
    print(request.auth, request.user.id, self.request.META.get('HTTP_AUTHORIZATION'))

AttributeError: 'dict' object has no attribute 'id'

}}}

{{{
<WSGIRequest: PUT '/api/account/userInfo/'>
}}}
Traceback (most recent call last):
  File "C:\Users\项波\Desktop\flower-service\venv\lib\site-packages\django\core\handlers\base.py", line 113, in _get_response
    response = wrapped_callback(request, *callback_args, **callback_kwargs)
  File "C:\Users\项波\Desktop\flower-service\venv\lib\site-packages\django\views\decorators\csrf.py", line 54, in wrapped_view
    return view_func(*args, **kwargs)
  File "C:\Users\项波\Desktop\flower-service\venv\lib\site-packages\django\views\generic\base.py", line 71, in view
    return self.dispatch(request, *args, **kwargs)
  File "C:\Users\项波\Desktop\flower-service\venv\lib\site-packages\rest_framework\views.py", line 497, in dispatch
    response = self.handle_exception(exc)
  File "C:\Users\项波\Desktop\flower-service\venv\lib\site-packages\rest_framework\views.py", line 457, in handle_exception
    self.raise_uncaught_exception(exc)
  File "C:\Users\项波\Desktop\flower-service\venv\lib\site-packages\rest_framework\views.py", line 468, in raise_uncaught_exception
    raise exc
  File "C:\Users\项波\Desktop\flower-service\venv\lib\site-packages\rest_framework\views.py", line 494, in dispatch
    response = handler(request, *args, **kwargs)
  File "C:\Users\项波\Desktop\flower-service\src\apps\common\decorator.py", line 17, in _func
    resp = func(*args, **kwargs)
  File "C:\Users\项波\Desktop\flower-service\src\apps\account\apis.py", line 118, in put
    print(request.auth, request.user.id, self.request.META.get('HTTP_AUTHORIZATION'))
AttributeError: 'dict' object has no attribute 'id'
2019-09-01 23:46:10,697 [Thread-3:9264] [service_mart.common.decorator:52] [ERROR]- error:error response:'MyUser' object has no attribute 'update'
2019-09-01 23:46:10,698 [Thread-3:9264] [service_mart.helper.middleware:163] [ERROR]- {{{
Traceback (most recent call last):

  File "C:\Users\项波\Desktop\flower-service\venv\lib\site-packages\django\core\handlers\base.py", line 113, in _get_response
    response = wrapped_callback(request, *callback_args, **callback_kwargs)

  File "C:\Users\项波\Desktop\flower-service\venv\lib\site-packages\django\views\decorators\csrf.py", line 54, in wrapped_view
    return view_func(*args, **kwargs)

  File "C:\Users\项波\Desktop\flower-service\venv\lib\site-packages\django\views\generic\base.py", line 71, in view
    return self.dispatch(request, *args, **kwargs)

  File "C:\Users\项波\Desktop\flower-service\venv\lib\site-packages\rest_framework\views.py", line 497, in dispatch
    response = self.handle_exception(exc)

  File "C:\Users\项波\Desktop\flower-service\venv\lib\site-packages\rest_framework\views.py", line 457, in handle_exception
    self.raise_uncaught_exception(exc)

  File "C:\Users\项波\Desktop\flower-service\venv\lib\site-packages\rest_framework\views.py", line 468, in raise_uncaught_exception
    raise exc

  File "C:\Users\项波\Desktop\flower-service\venv\lib\site-packages\rest_framework\views.py", line 494, in dispatch
    response = handler(request, *args, **kwargs)

  File "C:\Users\项波\Desktop\flower-service\src\apps\common\decorator.py", line 17, in _func
    resp = func(*args, **kwargs)

  File "C:\Users\项波\Desktop\flower-service\src\apps\account\apis.py", line 124, in put
    user = MyUser.objects.get(id=user_id).update(

AttributeError: 'MyUser' object has no attribute 'update'

}}}

{{{
<WSGIRequest: PUT '/api/account/userInfo/'>
}}}
Traceback (most recent call last):
  File "C:\Users\项波\Desktop\flower-service\venv\lib\site-packages\django\core\handlers\base.py", line 113, in _get_response
    response = wrapped_callback(request, *callback_args, **callback_kwargs)
  File "C:\Users\项波\Desktop\flower-service\venv\lib\site-packages\django\views\decorators\csrf.py", line 54, in wrapped_view
    return view_func(*args, **kwargs)
  File "C:\Users\项波\Desktop\flower-service\venv\lib\site-packages\django\views\generic\base.py", line 71, in view
    return self.dispatch(request, *args, **kwargs)
  File "C:\Users\项波\Desktop\flower-service\venv\lib\site-packages\rest_framework\views.py", line 497, in dispatch
    response = self.handle_exception(exc)
  File "C:\Users\项波\Desktop\flower-service\venv\lib\site-packages\rest_framework\views.py", line 457, in handle_exception
    self.raise_uncaught_exception(exc)
  File "C:\Users\项波\Desktop\flower-service\venv\lib\site-packages\rest_framework\views.py", line 468, in raise_uncaught_exception
    raise exc
  File "C:\Users\项波\Desktop\flower-service\venv\lib\site-packages\rest_framework\views.py", line 494, in dispatch
    response = handler(request, *args, **kwargs)
  File "C:\Users\项波\Desktop\flower-service\src\apps\common\decorator.py", line 17, in _func
    resp = func(*args, **kwargs)
  File "C:\Users\项波\Desktop\flower-service\src\apps\account\apis.py", line 124, in put
    user = MyUser.objects.get(id=user_id).update(
AttributeError: 'MyUser' object has no attribute 'update'
2019-09-01 23:52:17,844 [Thread-1:5600] [service_mart.common.decorator:52] [ERROR]- error:error response:invalid literal for int() with base 10: 'M'
2019-09-01 23:52:17,851 [Thread-1:5600] [service_mart.helper.middleware:163] [ERROR]- {{{
Traceback (most recent call last):

  File "C:\Users\项波\Desktop\flower-service\venv\lib\site-packages\django\core\handlers\base.py", line 113, in _get_response
    response = wrapped_callback(request, *callback_args, **callback_kwargs)

  File "C:\Users\项波\Desktop\flower-service\venv\lib\site-packages\django\views\decorators\csrf.py", line 54, in wrapped_view
    return view_func(*args, **kwargs)

  File "C:\Users\项波\Desktop\flower-service\venv\lib\site-packages\django\views\generic\base.py", line 71, in view
    return self.dispatch(request, *args, **kwargs)

  File "C:\Users\项波\Desktop\flower-service\venv\lib\site-packages\rest_framework\views.py", line 497, in dispatch
    response = self.handle_exception(exc)

  File "C:\Users\项波\Desktop\flower-service\venv\lib\site-packages\rest_framework\views.py", line 457, in handle_exception
    self.raise_uncaught_exception(exc)

  File "C:\Users\项波\Desktop\flower-service\venv\lib\site-packages\rest_framework\views.py", line 468, in raise_uncaught_exception
    raise exc

  File "C:\Users\项波\Desktop\flower-service\venv\lib\site-packages\rest_framework\views.py", line 494, in dispatch
    response = handler(request, *args, **kwargs)

  File "C:\Users\项波\Desktop\flower-service\src\apps\common\decorator.py", line 17, in _func
    resp = func(*args, **kwargs)

  File "C:\Users\项波\Desktop\flower-service\src\apps\account\apis.py", line 65, in post
    user.save()

  File "C:\Users\项波\Desktop\flower-service\venv\lib\site-packages\django\contrib\auth\base_user.py", line 66, in save
    super().save(*args, **kwargs)

  File "C:\Users\项波\Desktop\flower-service\venv\lib\site-packages\django\db\models\base.py", line 741, in save
    force_update=force_update, update_fields=update_fields)

  File "C:\Users\项波\Desktop\flower-service\venv\lib\site-packages\django\db\models\base.py", line 779, in save_base
    force_update, using, update_fields,

  File "C:\Users\项波\Desktop\flower-service\venv\lib\site-packages\django\db\models\base.py", line 851, in _save_table
    forced_update)

  File "C:\Users\项波\Desktop\flower-service\venv\lib\site-packages\django\db\models\base.py", line 900, in _do_update
    return filtered._update(values) > 0

  File "C:\Users\项波\Desktop\flower-service\venv\lib\site-packages\django\db\models\query.py", line 760, in _update
    return query.get_compiler(self.db).execute_sql(CURSOR)

  File "C:\Users\项波\Desktop\flower-service\venv\lib\site-packages\django\db\models\sql\compiler.py", line 1429, in execute_sql
    cursor = super().execute_sql(result_type)

  File "C:\Users\项波\Desktop\flower-service\venv\lib\site-packages\django\db\models\sql\compiler.py", line 1087, in execute_sql
    sql, params = self.as_sql()

  File "C:\Users\项波\Desktop\flower-service\venv\lib\site-packages\django\db\models\sql\compiler.py", line 1395, in as_sql
    val = field.get_db_prep_save(val, connection=self.connection)

  File "C:\Users\项波\Desktop\flower-service\venv\lib\site-packages\django\db\models\fields\__init__.py", line 789, in get_db_prep_save
    return self.get_db_prep_value(value, connection=connection, prepared=False)

  File "C:\Users\项波\Desktop\flower-service\venv\lib\site-packages\django\db\models\fields\__init__.py", line 784, in get_db_prep_value
    value = self.get_prep_value(value)

  File "C:\Users\项波\Desktop\flower-service\venv\lib\site-packages\django\db\models\fields\__init__.py", line 1819, in get_prep_value
    return int(value)

ValueError: invalid literal for int() with base 10: 'M'

}}}

{{{
<WSGIRequest: POST '/api/account/login/'>
}}}
Traceback (most recent call last):
  File "C:\Users\项波\Desktop\flower-service\venv\lib\site-packages\django\core\handlers\base.py", line 113, in _get_response
    response = wrapped_callback(request, *callback_args, **callback_kwargs)
  File "C:\Users\项波\Desktop\flower-service\venv\lib\site-packages\django\views\decorators\csrf.py", line 54, in wrapped_view
    return view_func(*args, **kwargs)
  File "C:\Users\项波\Desktop\flower-service\venv\lib\site-packages\django\views\generic\base.py", line 71, in view
    return self.dispatch(request, *args, **kwargs)
  File "C:\Users\项波\Desktop\flower-service\venv\lib\site-packages\rest_framework\views.py", line 497, in dispatch
    response = self.handle_exception(exc)
  File "C:\Users\项波\Desktop\flower-service\venv\lib\site-packages\rest_framework\views.py", line 457, in handle_exception
    self.raise_uncaught_exception(exc)
  File "C:\Users\项波\Desktop\flower-service\venv\lib\site-packages\rest_framework\views.py", line 468, in raise_uncaught_exception
    raise exc
  File "C:\Users\项波\Desktop\flower-service\venv\lib\site-packages\rest_framework\views.py", line 494, in dispatch
    response = handler(request, *args, **kwargs)
  File "C:\Users\项波\Desktop\flower-service\src\apps\common\decorator.py", line 17, in _func
    resp = func(*args, **kwargs)
  File "C:\Users\项波\Desktop\flower-service\src\apps\account\apis.py", line 65, in post
    user.save()
  File "C:\Users\项波\Desktop\flower-service\venv\lib\site-packages\django\contrib\auth\base_user.py", line 66, in save
    super().save(*args, **kwargs)
  File "C:\Users\项波\Desktop\flower-service\venv\lib\site-packages\django\db\models\base.py", line 741, in save
    force_update=force_update, update_fields=update_fields)
  File "C:\Users\项波\Desktop\flower-service\venv\lib\site-packages\django\db\models\base.py", line 779, in save_base
    force_update, using, update_fields,
  File "C:\Users\项波\Desktop\flower-service\venv\lib\site-packages\django\db\models\base.py", line 851, in _save_table
    forced_update)
  File "C:\Users\项波\Desktop\flower-service\venv\lib\site-packages\django\db\models\base.py", line 900, in _do_update
    return filtered._update(values) > 0
  File "C:\Users\项波\Desktop\flower-service\venv\lib\site-packages\django\db\models\query.py", line 760, in _update
    return query.get_compiler(self.db).execute_sql(CURSOR)
  File "C:\Users\项波\Desktop\flower-service\venv\lib\site-packages\django\db\models\sql\compiler.py", line 1429, in execute_sql
    cursor = super().execute_sql(result_type)
  File "C:\Users\项波\Desktop\flower-service\venv\lib\site-packages\django\db\models\sql\compiler.py", line 1087, in execute_sql
    sql, params = self.as_sql()
  File "C:\Users\项波\Desktop\flower-service\venv\lib\site-packages\django\db\models\sql\compiler.py", line 1395, in as_sql
    val = field.get_db_prep_save(val, connection=self.connection)
  File "C:\Users\项波\Desktop\flower-service\venv\lib\site-packages\django\db\models\fields\__init__.py", line 789, in get_db_prep_save
    return self.get_db_prep_value(value, connection=connection, prepared=False)
  File "C:\Users\项波\Desktop\flower-service\venv\lib\site-packages\django\db\models\fields\__init__.py", line 784, in get_db_prep_value
    value = self.get_prep_value(value)
  File "C:\Users\项波\Desktop\flower-service\venv\lib\site-packages\django\db\models\fields\__init__.py", line 1819, in get_prep_value
    return int(value)
ValueError: invalid literal for int() with base 10: 'M'
2019-09-01 23:56:54,640 [Thread-1:10632] [service_mart.common.decorator:52] [ERROR]- error:error response:'MyUser' object has no attribute 'update'
2019-09-01 23:56:54,641 [Thread-1:10632] [service_mart.helper.middleware:163] [ERROR]- {{{
Traceback (most recent call last):

  File "C:\Users\项波\Desktop\flower-service\venv\lib\site-packages\django\core\handlers\base.py", line 113, in _get_response
    response = wrapped_callback(request, *callback_args, **callback_kwargs)

  File "C:\Users\项波\Desktop\flower-service\venv\lib\site-packages\django\views\decorators\csrf.py", line 54, in wrapped_view
    return view_func(*args, **kwargs)

  File "C:\Users\项波\Desktop\flower-service\venv\lib\site-packages\django\views\generic\base.py", line 71, in view
    return self.dispatch(request, *args, **kwargs)

  File "C:\Users\项波\Desktop\flower-service\venv\lib\site-packages\rest_framework\views.py", line 497, in dispatch
    response = self.handle_exception(exc)

  File "C:\Users\项波\Desktop\flower-service\venv\lib\site-packages\rest_framework\views.py", line 457, in handle_exception
    self.raise_uncaught_exception(exc)

  File "C:\Users\项波\Desktop\flower-service\venv\lib\site-packages\rest_framework\views.py", line 468, in raise_uncaught_exception
    raise exc

  File "C:\Users\项波\Desktop\flower-service\venv\lib\site-packages\rest_framework\views.py", line 494, in dispatch
    response = handler(request, *args, **kwargs)

  File "C:\Users\项波\Desktop\flower-service\src\apps\common\decorator.py", line 17, in _func
    resp = func(*args, **kwargs)

  File "C:\Users\项波\Desktop\flower-service\src\apps\account\apis.py", line 125, in put
    MyUser.objects.get(id=user_id).update(

AttributeError: 'MyUser' object has no attribute 'update'

}}}

{{{
<WSGIRequest: PUT '/api/account/userInfo/'>
}}}
Traceback (most recent call last):
  File "C:\Users\项波\Desktop\flower-service\venv\lib\site-packages\django\core\handlers\base.py", line 113, in _get_response
    response = wrapped_callback(request, *callback_args, **callback_kwargs)
  File "C:\Users\项波\Desktop\flower-service\venv\lib\site-packages\django\views\decorators\csrf.py", line 54, in wrapped_view
    return view_func(*args, **kwargs)
  File "C:\Users\项波\Desktop\flower-service\venv\lib\site-packages\django\views\generic\base.py", line 71, in view
    return self.dispatch(request, *args, **kwargs)
  File "C:\Users\项波\Desktop\flower-service\venv\lib\site-packages\rest_framework\views.py", line 497, in dispatch
    response = self.handle_exception(exc)
  File "C:\Users\项波\Desktop\flower-service\venv\lib\site-packages\rest_framework\views.py", line 457, in handle_exception
    self.raise_uncaught_exception(exc)
  File "C:\Users\项波\Desktop\flower-service\venv\lib\site-packages\rest_framework\views.py", line 468, in raise_uncaught_exception
    raise exc
  File "C:\Users\项波\Desktop\flower-service\venv\lib\site-packages\rest_framework\views.py", line 494, in dispatch
    response = handler(request, *args, **kwargs)
  File "C:\Users\项波\Desktop\flower-service\src\apps\common\decorator.py", line 17, in _func
    resp = func(*args, **kwargs)
  File "C:\Users\项波\Desktop\flower-service\src\apps\account\apis.py", line 125, in put
    MyUser.objects.get(id=user_id).update(
AttributeError: 'MyUser' object has no attribute 'update'
